Workbook

Sheet Acompanhamento
A2: WEEK | B2: 2023 | C2: 1 | D2: 2 | E2: 3 | F2: 4 | G2: 5 | H2: 6 | I2: 7 | J2: 8 | K2: 9 | L2: 10 | M2: 11 | N2: 12 | O2: 13 | P2: 14 | Q2: 15 | R2: 16 | S2: 17 | T2: 18 | U2: 19 | V2: 20 | W2: 21 | X2: 22 | Y2: 23 | Z2: 24 | AA2: 25 | AB2: 26 | AC2: 27 | AD2: 28 | AE2: 29 | AF2: 30 | AG2: 31 | AH2: 32 | AI2: 33 | AJ2: 34 | AK2: 35 | AL2: 36 | AM2: 37 | AN2: 38 | AO2: 39 | AP2: 40 | AQ2: 41 | AR2: 42 | AS2: 43 | AT2: 44 | AU2: 45 | AV2: 46 | AW2: 47 | AX2: 48 | AY2: 49 | AZ2: 50 | BA2: 51 | BB2: 52 | BC2: Total | BE2: Recebido GEM 2023 | BF2: =SUM($C$3:$BB$3) -> 235
A3: GEM | B3: Recebido | C3: =COUNTIFS('Controle de CR'!$A:$A,Acompanhamento!$B$2,'Controle de CR'!$B:$B,Acompanhamento!C$2,'Controle de CR'!$G:$G,Acompanhamento!$A$3) -> 3 | D3: =COUNTIFS('Controle de CR'!$A:$A,Acompanhamento!$B$2,'Controle de CR'!$B:$B,Acompanhamento!D$2,'Controle de CR'!$G:$G,Acompanhamento!$A$3) -> 4 | E3: =COUNTIFS('Controle de CR'!$A:$A,Acompanhamento!$B$2,'Controle de CR'!$B:$B,Acompanhamento!E$2,'Controle de CR'!$G:$G,Acompanhamento!$A$3) -> 8 | F3: =COUNTIFS('Controle de CR'!$A:$A,Acompanhamento!$B$2,'Controle de CR'!$B:$B,Acompanhamento!F$2,'Controle de CR'!$G:$G,Acompanhamento!$A$3) -> 5 | G3: =COUNTIFS('Controle de CR'!$A:$A,Acompanhamento!$B$2,'Controle de CR'!$B:$B,Acompanhamento!G$2,'Controle de CR'!$G:$G,Acompanhamento!$A$3) -> 4 | H3: =COUNTIFS('Controle de CR'!$A:$A,Acompanhamento!$B$2,'Controle de CR'!$B:$B,Acompanhamento!H$2,'Controle de CR'!$G:$G,Acompanhamento!$A$3) -> 2 | I3: =COUNTIFS('Controle de CR'!$A:$A,Acompanhamento!$B$2,'Controle de CR'!$B:$B,Acompanhamento!I$2,'Controle de CR'!$G:$G,Acompanhamento!$A$3) -> 1 | J3: =COUNTIFS('Controle de CR'!$A:$A,Acompanhamento!$B$2,'Controle de CR'!$B:$B,Acompanhamento!J$2,'Controle de CR'!$G:$G,Acompanhamento!$A$3) -> 5 | ... BB3: =COUNTIFS('Controle de CR'!$A:$A,Acompanhamento!$B$2,'Controle de CR'!$B:$B,Acompanhamento!BB$2,'Controle de CR'!$G:$G,Acompanhamento!$A$3) -> 0 | BC3: =SUM(C3:BB3) -> 235 | BE3: Respondido GEM 2023 | BF3: =SUM($C$4:$BB$4) -> 237
A4: GEM | B4: Respondido | C4: =COUNTIFS('Controle de CR'!$A:$A,Acompanhamento!$B$2,'Controle de CR'!$C:$C,Acompanhamento!C$2,'Controle de CR'!$G:$G,Acompanhamento!$A$4) -> 5 | D4: =COUNTIFS('Controle de CR'!$A:$A,Acompanhamento!$B$2,'Controle de CR'!$C:$C,Acompanhamento!D$2,'Controle de CR'!$G:$G,Acompanhamento!$A$4) -> 2 | E4: =COUNTIFS('Controle de CR'!$A:$A,Acompanhamento!$B$2,'Controle de CR'!$C:$C,Acompanhamento!E$2,'Controle de CR'!$G:$G,Acompanhamento!$A$4) -> 4 | F4: =COUNTIFS('Controle de CR'!$A:$A,Acompanhamento!$B$2,'Controle de CR'!$C:$C,Acompanhamento!F$2,'Controle de CR'!$G:$G,Acompanhamento!$A$4) -> 10 | G4: =COUNTIFS('Controle de CR'!$A:$A,Acompanhamento!$B$2,'Controle de CR'!$C:$C,Acompanhamento!G$2,'Controle de CR'!$G:$G,Acompanhamento!$A$4) -> 1 | H4: =COUNTIFS('Controle de CR'!$A:$A,Acompanhamento!$B$2,'Controle de CR'!$C:$C,Acompanhamento!H$2,'Controle de CR'!$G:$G,Acompanhamento!$A$4) -> 6 | I4: =COUNTIFS('Controle de CR'!$A:$A,Acompanhamento!$B$2,'Controle de CR'!$C:$C,Acompanhamento!I$2,'Controle de CR'!$G:$G,Acompanhamento!$A$4) -> 0 | J4: =COUNTIFS('Controle de CR'!$A:$A,Acompanhamento!$B$2,'Controle de CR'!$C:$C,Acompanhamento!J$2,'Controle de CR'!$G:$G,Acompanhamento!$A$4) -> 6 | ... BB4: =COUNTIFS('Controle de CR'!$A:$A,Acompanhamento!$B$2,'Controle de CR'!$C:$C,Acompanhamento!BB$2,'Controle de CR'!$G:$G,Acompanhamento!$A$4) -> 2 | BC4: =SUM(C4:BB4) -> 237 | BE4: RecebidoVS30 2023 | BF4: =SUM($C$7:$BB$7) -> 88
A5: GEM | B5: Falta Responder | C5: =C3-C4 -> -2 | D5: =D3-D4 -> 2 | E5: =E3-E4 -> 4 | F5: =F3-F4 -> -5 | G5: =G3-G4 -> 3 | H5: =H3-H4 -> -4 | I5: =I3-I4 -> 1 | J5: =J3-J4 -> -1 | ... BB5: =BB3-BB4 -> -2 | BC5: =SUM(C5:BB5) -> -2 | BE5: Respondido VS30 2023 | BF5: =SUM($C$8:$BB$8) -> 88
A7: VS30 | B7: Recebido | C7: =COUNTIFS('Controle de CR'!$A:$A,Acompanhamento!$B$2,'Controle de CR'!$B:$B,Acompanhamento!C$2,'Controle de CR'!$G:$G,Acompanhamento!$A$7) -> 0 | D7: =COUNTIFS('Controle de CR'!$A:$A,Acompanhamento!$B$2,'Controle de CR'!$B:$B,Acompanhamento!D$2,'Controle de CR'!$G:$G,Acompanhamento!$A$7) -> 1 | E7: =COUNTIFS('Controle de CR'!$A:$A,Acompanhamento!$B$2,'Controle de CR'!$B:$B,Acompanhamento!E$2,'Controle de CR'!$G:$G,Acompanhamento!$A$7) -> 0 | F7: =COUNTIFS('Controle de CR'!$A:$A,Acompanhamento!$B$2,'Controle de CR'!$B:$B,Acompanhamento!F$2,'Controle de CR'!$G:$G,Acompanhamento!$A$7) -> 0 | G7: =COUNTIFS('Controle de CR'!$A:$A,Acompanhamento!$B$2,'Controle de CR'!$B:$B,Acompanhamento!G$2,'Controle de CR'!$G:$G,Acompanhamento!$A$7) -> 0 | H7: =COUNTIFS('Controle de CR'!$A:$A,Acompanhamento!$B$2,'Controle de CR'!$B:$B,Acompanhamento!H$2,'Controle de CR'!$G:$G,Acompanhamento!$A$7) -> 2 | I7: =COUNTIFS('Controle de CR'!$A:$A,Acompanhamento!$B$2,'Controle de CR'!$B:$B,Acompanhamento!I$2,'Controle de CR'!$G:$G,Acompanhamento!$A$7) -> 0 | J7: =COUNTIFS('Controle de CR'!$A:$A,Acompanhamento!$B$2,'Controle de CR'!$B:$B,Acompanhamento!J$2,'Controle de CR'!$G:$G,Acompanhamento!$A$7) -> 0 | ... BB7: =COUNTIFS('Controle de CR'!$A:$A,Acompanhamento!$B$2,'Controle de CR'!$B:$B,Acompanhamento!BB$2,'Controle de CR'!$G:$G,Acompanhamento!$A$7) -> 0 | BC7: =SUM(C7:BB7) -> 88
A8: VS30 | B8: Respondido | C8: =COUNTIFS('Controle de CR'!$A:$A,Acompanhamento!$B$2,'Controle de CR'!$C:$C,Acompanhamento!C$2,'Controle de CR'!$G:$G,Acompanhamento!$A$8) -> 0 | D8: =COUNTIFS('Controle de CR'!$A:$A,Acompanhamento!$B$2,'Controle de CR'!$C:$C,Acompanhamento!D$2,'Controle de CR'!$G:$G,Acompanhamento!$A$8) -> 0 | E8: =COUNTIFS('Controle de CR'!$A:$A,Acompanhamento!$B$2,'Controle de CR'!$C:$C,Acompanhamento!E$2,'Controle de CR'!$G:$G,Acompanhamento!$A$8) -> 1 | F8: =COUNTIFS('Controle de CR'!$A:$A,Acompanhamento!$B$2,'Controle de CR'!$C:$C,Acompanhamento!F$2,'Controle de CR'!$G:$G,Acompanhamento!$A$8) -> 0 | G8: =COUNTIFS('Controle de CR'!$A:$A,Acompanhamento!$B$2,'Controle de CR'!$C:$C,Acompanhamento!G$2,'Controle de CR'!$G:$G,Acompanhamento!$A$8) -> 1 | H8: =COUNTIFS('Controle de CR'!$A:$A,Acompanhamento!$B$2,'Controle de CR'!$C:$C,Acompanhamento!H$2,'Controle de CR'!$G:$G,Acompanhamento!$A$8) -> 2 | I8: =COUNTIFS('Controle de CR'!$A:$A,Acompanhamento!$B$2,'Controle de CR'!$C:$C,Acompanhamento!I$2,'Controle de CR'!$G:$G,Acompanhamento!$A$8) -> 1 | J8: =COUNTIFS('Controle de CR'!$A:$A,Acompanhamento!$B$2,'Controle de CR'!$C:$C,Acompanhamento!J$2,'Controle de CR'!$G:$G,Acompanhamento!$A$8) -> 0 | ... BB8: =COUNTIFS('Controle de CR'!$A:$A,Acompanhamento!$B$2,'Controle de CR'!$C:$C,Acompanhamento!BB$2,'Controle de CR'!$G:$G,Acompanhamento!$A$8) -> 0 | BC8: =SUM(C8:BB8) -> 88
A9: VS30 | B9: Falta Responder | C9: =C7-C8 -> 0 | D9: =D7-D8 -> 1 | E9: =E7-E8 -> -1 | F9: =F7-F8 -> 0 | G9: =G7-G8 -> -1 | H9: =H7-H8 -> 0 | I9: =I7-I8 -> -1 | J9: =J7-J8 -> 0 | ... BB9: =BB7-BB8 -> 0 | BC9: =SUM(C9:BB9) -> 0
A11: SPIN | B11: Recebido | C11: =COUNTIFS('Controle de CR'!$A:$A,Acompanhamento!$B$2,'Controle de CR'!$B:$B,Acompanhamento!C$2,'Controle de CR'!$G:$G,Acompanhamento!$A$11) -> 1 | D11: =COUNTIFS('Controle de CR'!$A:$A,Acompanhamento!$B$2,'Controle de CR'!$B:$B,Acompanhamento!D$2,'Controle de CR'!$G:$G,Acompanhamento!$A$11) -> 6 | E11: =COUNTIFS('Controle de CR'!$A:$A,Acompanhamento!$B$2,'Controle de CR'!$B:$B,Acompanhamento!E$2,'Controle de CR'!$G:$G,Acompanhamento!$A$11) -> 11 | F11: =COUNTIFS('Controle de CR'!$A:$A,Acompanhamento!$B$2,'Controle de CR'!$B:$B,Acompanhamento!F$2,'Controle de CR'!$G:$G,Acompanhamento!$A$11) -> 13 | G11: =COUNTIFS('Controle de CR'!$A:$A,Acompanhamento!$B$2,'Controle de CR'!$B:$B,Acompanhamento!G$2,'Controle de CR'!$G:$G,Acompanhamento!$A$11) -> 7 | H11: =COUNTIFS('Controle de CR'!$A:$A,Acompanhamento!$B$2,'Controle de CR'!$B:$B,Acompanhamento!H$2,'Controle de CR'!$G:$G,Acompanhamento!$A$11) -> 14 | I11: =COUNTIFS('Controle de CR'!$A:$A,Acompanhamento!$B$2,'Controle de CR'!$B:$B,Acompanhamento!I$2,'Controle de CR'!$G:$G,Acompanhamento!$A$11) -> 15 | J11: =COUNTIFS('Controle de CR'!$A:$A,Acompanhamento!$B$2,'Controle de CR'!$B:$B,Acompanhamento!J$2,'Controle de CR'!$G:$G,Acompanhamento!$A$11) -> 2 | ... BB11: =COUNTIFS('Controle de CR'!$A:$A,Acompanhamento!$B$2,'Controle de CR'!$B:$B,Acompanhamento!BB$2,'Controle de CR'!$G:$G,Acompanhamento!$A$11) -> 0 | BC11: =SUM(C11:BB11) -> 219
A12: SPIN | B12: Respondido | C12: =COUNTIFS('Controle de CR'!$A:$A,Acompanhamento!$B$2,'Controle de CR'!$C:$C,Acompanhamento!C$2,'Controle de CR'!$G:$G,Acompanhamento!$A$12) -> 5 | D12: =COUNTIFS('Controle de CR'!$A:$A,Acompanhamento!$B$2,'Controle de CR'!$C:$C,Acompanhamento!D$2,'Controle de CR'!$G:$G,Acompanhamento!$A$12) -> 5 | E12: =COUNTIFS('Controle de CR'!$A:$A,Acompanhamento!$B$2,'Controle de CR'!$C:$C,Acompanhamento!E$2,'Controle de CR'!$G:$G,Acompanhamento!$A$12) -> 4 | F12: =COUNTIFS('Controle de CR'!$A:$A,Acompanhamento!$B$2,'Controle de CR'!$C:$C,Acompanhamento!F$2,'Controle de CR'!$G:$G,Acompanhamento!$A$12) -> 7 | G12: =COUNTIFS('Controle de CR'!$A:$A,Acompanhamento!$B$2,'Controle de CR'!$C:$C,Acompanhamento!G$2,'Controle de CR'!$G:$G,Acompanhamento!$A$12) -> 18 | H12: =COUNTIFS('Controle de CR'!$A:$A,Acompanhamento!$B$2,'Controle de CR'!$C:$C,Acompanhamento!H$2,'Controle de CR'!$G:$G,Acompanhamento!$A$12) -> 16 | I12: =COUNTIFS('Controle de CR'!$A:$A,Acompanhamento!$B$2,'Controle de CR'!$C:$C,Acompanhamento!I$2,'Controle de CR'!$G:$G,Acompanhamento!$A$12) -> 11 | J12: =COUNTIFS('Controle de CR'!$A:$A,Acompanhamento!$B$2,'Controle de CR'!$C:$C,Acompanhamento!J$2,'Controle de CR'!$G:$G,Acompanhamento!$A$12) -> 3 | ... BB12: =COUNTIFS('Controle de CR'!$A:$A,Acompanhamento!$B$2,'Controle de CR'!$C:$C,Acompanhamento!BB$2,'Controle de CR'!$G:$G,Acompanhamento!$A$12) -> 0 | BC12: =SUM(C12:BB12) -> 223
A13: VS30 | B13: Falta Responder | C13: =C11-C12 -> -4 | D13: =D11-D12 -> 1 | E13: =E11-E12 -> 7 | F13: =F11-F12 -> 6 | G13: =G11-G12 -> -11 | H13: =H11-H12 -> -2 | I13: =I11-I12 -> 4 | J13: =J11-J12 -> -1 | ... BB13: =BB11-BB12 -> 0 | BC13: =SUM(C13:BB13) -> -4
BC15: Total
B16: Marcelo Santos | C16: =COUNTIFS('Controle de CR'!$A:$A,Acompanhamento!$B$2,'Controle de CR'!$K:$K,Acompanhamento!$B$16,'Controle de CR'!$C:$C,Acompanhamento!C$2) -> 5 | D16: =COUNTIFS('Controle de CR'!$A:$A,Acompanhamento!$B$2,'Controle de CR'!$K:$K,Acompanhamento!$B$16,'Controle de CR'!$C:$C,Acompanhamento!D$2) -> 2 | E16: =COUNTIFS('Controle de CR'!$A:$A,Acompanhamento!$B$2,'Controle de CR'!$K:$K,Acompanhamento!$B$16,'Controle de CR'!$C:$C,Acompanhamento!E$2) -> 9 | F16: =COUNTIFS('Controle de CR'!$A:$A,Acompanhamento!$B$2,'Controle de CR'!$K:$K,Acompanhamento!$B$16,'Controle de CR'!$C:$C,Acompanhamento!F$2) -> 15 | G16: =COUNTIFS('Controle de CR'!$A:$A,Acompanhamento!$B$2,'Controle de CR'!$K:$K,Acompanhamento!$B$16,'Controle de CR'!$C:$C,Acompanhamento!G$2) -> 10 | H16: =COUNTIFS('Controle de CR'!$A:$A,Acompanhamento!$B$2,'Controle de CR'!$K:$K,Acompanhamento!$B$16,'Controle de CR'!$C:$C,Acompanhamento!H$2) -> 5 | I16: =COUNTIFS('Controle de CR'!$A:$A,Acompanhamento!$B$2,'Controle de CR'!$K:$K,Acompanhamento!$B$16,'Controle de CR'!$C:$C,Acompanhamento!I$2) -> 0 | J16: =COUNTIFS('Controle de CR'!$A:$A,Acompanhamento!$B$2,'Controle de CR'!$K:$K,Acompanhamento!$B$16,'Controle de CR'!$C:$C,Acompanhamento!J$2) -> 0 | ... BB16: =COUNTIFS('Controle de CR'!$A:$A,Acompanhamento!$B$2,'Controle de CR'!$K:$K,Acompanhamento!$B$16,'Controle de CR'!$C:$C,Acompanhamento!BB$2) -> 2 | BC16: =SUM(C16:BB16) -> 216
B17: Paulo Lima | C17: =COUNTIFS('Controle de CR'!$A:$A,Acompanhamento!$B$2,'Controle de CR'!$K:$K,Acompanhamento!$B$17,'Controle de CR'!$C:$C,Acompanhamento!C$2) -> 5 | D17: =COUNTIFS('Controle de CR'!$A:$A,Acompanhamento!$B$2,'Controle de CR'!$K:$K,Acompanhamento!$B$17,'Controle de CR'!$C:$C,Acompanhamento!D$2) -> 5 | E17: =COUNTIFS('Controle de CR'!$A:$A,Acompanhamento!$B$2,'Controle de CR'!$K:$K,Acompanhamento!$B$17,'Controle de CR'!$C:$C,Acompanhamento!E$2) -> 0 | F17: =COUNTIFS('Controle de CR'!$A:$A,Acompanhamento!$B$2,'Controle de CR'!$K:$K,Acompanhamento!$B$17,'Controle de CR'!$C:$C,Acompanhamento!F$2) -> 2 | G17: =COUNTIFS('Controle de CR'!$A:$A,Acompanhamento!$B$2,'Controle de CR'!$K:$K,Acompanhamento!$B$17,'Controle de CR'!$C:$C,Acompanhamento!G$2) -> 10 | H17: =COUNTIFS('Controle de CR'!$A:$A,Acompanhamento!$B$2,'Controle de CR'!$K:$K,Acompanhamento!$B$17,'Controle de CR'!$C:$C,Acompanhamento!H$2) -> 19 | I17: =COUNTIFS('Controle de CR'!$A:$A,Acompanhamento!$B$2,'Controle de CR'!$K:$K,Acompanhamento!$B$17,'Controle de CR'!$C:$C,Acompanhamento!I$2) -> 12 | J17: =COUNTIFS('Controle de CR'!$A:$A,Acompanhamento!$B$2,'Controle de CR'!$K:$K,Acompanhamento!$B$17,'Controle de CR'!$C:$C,Acompanhamento!J$2) -> 9 | ... BB17: =COUNTIFS('Controle de CR'!$A:$A,Acompanhamento!$B$2,'Controle de CR'!$K:$K,Acompanhamento!$B$17,'Controle de CR'!$C:$C,Acompanhamento!BB$2) -> 0 | BC17: =SUM(C17:BB17) -> 333

Sheet Controle de CR
A1: Ano | B1: Recebida Week | C1: Respondida Week | D1: DCN | E1: CR | F1: IP | G1: Projeto | H1: Nome Resp. CR | I1: Data | J1: Hora | K1: Avaliado | L1: Data | M1: Hora | N1: OBSERVAÇÃO | O1: OBSERVAÇÃO 02
A2: =YEAR(L2) -> 1900 | B2: =WEEKNUM(I2) -> 37 | C2: =WEEKNUM(L2) -> 0 | E2: CR-0110061-00 | H2: Marcio Militani | I2: 44447 | J2: 0.38472222 | K2: Paulo Lima | N2: Sem impacto em Lead Prep! Implementação condicionada à aprovação da aplicação sob a norma GMW 17136
A3: =YEAR(L3) -> 1900 | B3: =WEEKNUM(I3) -> 37 | C3: =WEEKNUM(L3) -> 0 | E3: - | F3: ISS-026302 | H3: Gabriel conceição | I3: 44447 | J3: 0.24375 | K3: Paulo Lima
A4: =YEAR(L4) -> 1900 | B4: =WEEKNUM(I4) -> 35 | C4: =WEEKNUM(L4) -> 0 | E4: CR-0109316-00 | G4: VS30 | H4: Marcio Militani | I4: 44435 | J4: 0.67430556 | K4: Paulo Lima | N4: Sem Impacto
A5: =YEAR(L5) -> 1900 | B5: =WEEKNUM(I5) -> 35 | C5: =WEEKNUM(L5) -> 0 | E5: CR-0109284-00 | G5: VS30 | H5: Marcio Militani | I5: 44435 | J5: 0.67152778 | K5: Paulo Lima | N5: Sem Impacto
A6: =YEAR(L6) -> 1900 | B6: =WEEKNUM(I6) -> 35 | C6: =WEEKNUM(L6) -> 0 | E6: CR-0109320-00 | G6: VS30 | H6: Marcio Militani | I6: 44435 | J6: 0.67638889 | K6: Paulo Lima | N6: Sem Impacto
A7: =YEAR(L7) -> 1900 | B7: =WEEKNUM(I7) -> 35 | C7: =WEEKNUM(L7) -> 0 | E7: CR-0109534-00 | G7: GEM | H7: Marcio Militani | I7: 44435 | J7: 0.68680556 | K7: Paulo Lima | N7: Sem Impacto
A8: =YEAR(L8) -> 1900 | B8: =WEEKNUM(I8) -> 35 | C8: =WEEKNUM(L8) -> 0 | E8: CR-0109404-00 | G8: GEM | H8: Marcio Militani | I8: 44435 | J8: 0.69027778 | K8: Paulo Lima | N8: Sem Impacto
A9: =YEAR(L9) -> 1900 | B9: =WEEKNUM(I9) -> 36 | C9: =WEEKNUM(L9) -> 0 | E9: CR-0109163-00 | G9: VS30 | H9: Marcio Militani | I9: 44439 | J9: 0.37777778 | K9: Paulo Lima | N9: Sem Impacto
A10: =YEAR(L10) -> 1900 | B10: =WEEKNUM(I10) -> 36 | C10: =WEEKNUM(L10) -> 0 | E10: CR-0108981-00 | G10: GEM MY 22 e 22/5 | H10: Marcio Militani | I10: 44439 | J10: 0.37916667 | K10: Paulo Lima | N10: Sem Impacto
A11: =YEAR(L11) -> 1900 | B11: =WEEKNUM(I11) -> 36 | C11: =WEEKNUM(L11) -> 0 | E11: CR-0109174-00 | G11: GEM MY 22.5 | H11: Marcio Militani | I11: 44439 | J11: 0.37708333 | K11: Paulo Lima | N11: Due to the transfer of machinery of GMI to Camanducaia, we do not have a machine to cut the E03239500 tube and it is necessary to replace it with the E21429600. Verificar esta CR com relação a esta troca de tubo | O11: OK
A12: =YEAR(L12) -> 1900 | B12: =WEEKNUM(I12) -> 36 | C12: =WEEKNUM(L12) -> 0 | E12: CR-0109003-00 | G12: GEM | H12: Marcio Militani | I12: 44439 | J12: 0.38055556 | K12: Paulo Lima | N12: Sem Impacto
A13: =YEAR(L13) -> 1900 | B13: =WEEKNUM(I13) -> 36 | C13: =WEEKNUM(L13) -> 0 | E13: CR's PENDENTES | H13: Marcio Militani | I13: 44439 | J13: 0.38125 | K13: Paulo Lima | N13: Verificar com o Márcio sobre as CR'spendentes
A14: =YEAR(L14) -> 1900 | B14: =WEEKNUM(I14) -> 36 | C14: =WEEKNUM(L14) -> 0 | E14: CR's PENDENTES | H14: Marcio Militani | I14: 44439 | J14: 0.3875 | K14: Paulo Lima | N14: Verificar com o Márcio sobre as CR'spendentes
A15: =YEAR(L15) -> 1900 | B15: =WEEKNUM(I15) -> 36 | C15: =WEEKNUM(L15) -> 0 | E15: CR-0109151-00 | G15: GEM MY 22.5 | H15: Marcio Militani | I15: 44439 | J15: 0.39791667 | K15: Paulo Lima | N15: Due to the transfer of machinery of GMI to Camanducaia, we do not have a machine to cut the E03239500 tube and it is necessary to replace it with the E21429700.Verificar esta CR com relação a esta troca de tubo | O15: Não tem matéria prima para efetuar o teste
A16: =YEAR(L16) -> 1900 | B16: =WEEKNUM(I16) -> 36 | C16: =WEEKNUM(L16) -> 0 | D16: DCN-2021-0010462-VS30-4 | E16: CR-0107176-01 | G16: VS30 | H16: Robson Avelino | I16: 44439 | J16: 0.83680556 | K16: Paulo Lima | N16: Sem Impacto
A17: =YEAR(L17) -> 1900 | B17: =WEEKNUM(I17) -> 36 | C17: =WEEKNUM(L17) -> 0 | D17: DCN-2021-0010464-VS30-4 | E17: CR-0107174-00 | G17: VS30 | H17: Robson Avelino | I17: 44439 | J17: 0.83680556 | K17: Paulo Lima | N17: Sem Impacto
A18: =YEAR(L18) -> 1900 | B18: =WEEKNUM(I18) -> 36 | C18: =WEEKNUM(L18) -> 0 | D18: DCN-2021-0010465-VS30-4 | E18: CR-0107964-00 | G18: VS30 | H18: Robson Avelino | I18: 44439 | J18: 0.83680556 | K18: Paulo Lima | N18: Sem Impacto
A19: =YEAR(L19) -> 1900 | B19: =WEEKNUM(I19) -> 36 | C19: =WEEKNUM(L19) -> 0 | D19: DCN-2021-0010466-VS30-4 | E19: CR-0107970-00/ | G19: VS30 | H19: Robson Avelino | I19: 44439 | J19: 0.83680556 | K19: Paulo Lima | N19: Não achei na lista de terminal, favor avaliar | O19: Sendo avaliado pelo Rogerio
A20: =YEAR(L20) -> 1900 | B20: =WEEKNUM(I20) -> 36 | C20: =WEEKNUM(L20) -> 0 | D20: DCN-2021-0010467-VS30-4 | E20: CR-0107590-00 | G20: VS30 | H20: Robson Avelino | I20: 44439 | J20: 0.83680556 | K20: Paulo Lima | N20: Sem Impacto
A21: =YEAR(L21) -> 1900 | B21: =WEEKNUM(I21) -> 36 | C21: =WEEKNUM(L21) -> 0 | D21: DCN-2021-0010126-GEM-4 | E21: CR-0102325-00 | G21: GEM | H21: Rogerio Naus | I21: 44441 | J21: 0.36458333 | K21: Paulo Lima | N21: Alteração de termo retrátil de GPN-E15828200/GPN-E02090100 (27mm) para GPN-E30547700 (40mm) do terminal olhal X633G108_DIRTY_X1. Complementado a CR-0102835-00 é necessário adição de mastic de GPN-E24835800 no terminal olhal X633G108_DIRTY_X1. Utilizar 1g (grama) de mastic para cada aplicação do termo retrátil GPN-E30547700 + mastic GPN-E24835800
A22: =YEAR(L22) -> 1900 | B22: =WEEKNUM(I22) -> 36 | C22: =WEEKNUM(L22) -> 0 | D22: DCN-2021-0010127-GEM-4 | E22: CR-0102325-00 | G22: GEM | H22: Rogerio Naus | I22: 44441 | J22: 0.36458333 | K22: Paulo Lima | N22: Alteração de termo retrátil de GPN-E15828200/GPN-E02090100 (27mm) para GPN-E30547700 (40mm) do terminal olhal X633G108_DIRTY_X1. Complementado a CR-0102835-00 é necessário adição de mastic de GPN-E24835800 no terminal olhal X633G108_DIRTY_X1. Utilizar 1g (grama) de mastic para cada aplicação do termo retrátil GPN-E30547700 + mastic GPN-E24835800.
A23: =YEAR(L23) -> 1900 | B23: =WEEKNUM(I23) -> 36 | C23: =WEEKNUM(L23) -> 0 | D23: DCN-2021-0010128-GEM-4 | E23: CR-0102325-00 | G23: GEM | H23: Rogerio Naus | I23: 44441 | J23: 0.36458333 | K23: Paulo Lima | N23: Sem Impacto
A24: =YEAR(L24) -> 1900 | B24: =WEEKNUM(I24) -> 36 | C24: =WEEKNUM(L24) -> 0 | D24: DCN-2021-0010129-GEM-4 | E24: CR-0102325-00 | G24: GEM | H24: Rogerio Naus | I24: 44441 | J24: 0.36458333 | K24: Paulo Lima | N24: Sem Impacto
A25: =YEAR(L25) -> 1900 | B25: =WEEKNUM(I25) -> 36 | C25: =WEEKNUM(L25) -> 0 | D25: DCN-2021-0010171-GEM-4 | E25: CR-0102205-00 / CR-0102594-00 | G25: GEM | H25: Rogerio Naus | I25: 44441 | J25: 0.36666667 | K25: Paulo Lima | N25: Sem Impacto
A26: =YEAR(L26) -> 1900 | B26: =WEEKNUM(I26) -> 36 | C26: =WEEKNUM(L26) -> 0 | D26: DCN-2021-0010148-GEM-4 | E26: CR-0102545-00,CR-0102565-00,CR-0102567-00,CR-0102603-00,CR-0102849-01 e CR-0102839-01 | G26: GEM | H26: Rogerio Naus | I26: 44441 | J26: 0.36805556 | K26: Paulo Lima | N26: Oficializando troca do terminal de E14568800 para E21821100 RN234. | O26: Já temos este terminal validado
A27: =YEAR(L27) -> 1900 | B27: =WEEKNUM(I27) -> 36 | C27: =WEEKNUM(L27) -> 0 | D27: DCN-2021-0010150-GEM-4 | E27: CR-0102546-00 | G27: GEM | H27: Rogerio Naus | I27: 44441 | J27: 0.36805556 | K27: Paulo Lima | N27: Oficializando troca do terminal de E14568800 para E21821100 RN243.
A28: =YEAR(L28) -> 1900 | B28: =WEEKNUM(I28) -> 38 | C28: =WEEKNUM(L28) -> 0 | E28: CR-0110114-00 | F28: ISS-026053 | G28: GEM | H28: Márcio Pericles Militani | I28: 44452 | J28: 0.45972222 | K28: Paulo Lima | N28: TW117_5 aumetando o comprimento de 720mm para 750 mm
A29: =YEAR(L29) -> 1900 | B29: =WEEKNUM(I29) -> 38 | C29: =WEEKNUM(L29) -> 0 | E29: CR-0110178-00 | G29: GEM | H29: Márcio Pericles Militani | I29: 44452 | J29: 0.47569444 | K29: Paulo Lima | N29: sem impacto
A30: =YEAR(L30) -> 1900 | B30: =WEEKNUM(I30) -> 38 | C30: =WEEKNUM(L30) -> 0 | E30: CR-0110179-00 | G30: GEM | H30: Márcio Pericles Militani | I30: 44452 | J30: 0.49305556 | K30: Paulo Lima | N30: WLL, STOCK IN USER
A31: =YEAR(L31) -> 1900 | B31: =WEEKNUM(I31) -> 38 | C31: =WEEKNUM(L31) -> 0 | E31: CR-0110382-00. | G31: VS30 | H31: Márcio Pericles Militani | I31: 44454 | J31: 0.31944444 | K31: Paulo Lima | N31: circuito 6651B-terminal de E09199300 para E11424400 / circuito 6652B - 6653B-6654B- terminal de 3201511A1 para E11225200 /
A32: =YEAR(L32) -> 1900 | B32: =WEEKNUM(I32) -> 39 | C32: =WEEKNUM(L32) -> 0 | E32: CR-0110673-00. | G32: VS30 | H32: Márcio Pericles Militani | I32: 44462 | J32: 0.48333333 | K32: Paulo Lima | N32: WLL DE SPLICE, MULTICRIMP E CIRCUITOS COMUNS. Sem necessidade de investimento
A33: =YEAR(L33) -> 1900 | B33: =WEEKNUM(I33) -> 39 | C33: =WEEKNUM(L33) -> 0 | E33: CR-0110672-00 | G33: GEM | H33: Márcio Pericles Militani | I33: 44462 | J33: 0.48888889 | K33: Paulo Lima | N33: Alteração de WLL e TLL. SEM NECESSIDADE DE INVESTIMENTO
A34: =YEAR(L34) -> 1900 | B34: =WEEKNUM(I34) -> 52 | C34: =WEEKNUM(L34) -> 0 | E34: CR-0115570-00 | G34: GEM | H34: Márcio Pericles Militani | I34: 44550 | J34: 0.63402778 | K34: Paulo Lima | N34: Troca do termoencolhível de E02000700 (65mm/135°C) para E16718500 (50mm/125°C) | O34: Necessário validação de todas as splices para aprovação. Total de 60 splices para fazer aa validação. Custo de R$2678,1 para as amostras
A35: =YEAR(L35) -> 1900 | B35: =WEEKNUM(I35) -> 52 | C35: =WEEKNUM(L35) -> 0 | E35: CR-0115703-00 | G35: GEM | H35: Marcelo | I35: 44551 | J35: 0.47777778 | K35: Paulo Lima | N35: Troca do terminal 3202532V5 para 3202650S8 | O35: Necessário investimento de um miniapicador, validação e peças de reposição. Aplicador novo
A36: =YEAR(L36) -> 1900 | B36: =WEEKNUM(I36) -> 52 | C36: =WEEKNUM(L36) -> 0 | E36: CR-0115655-00 | G36: GEM | H36: Marcelo | I36: 44552 | J36: 0.47986111 | K36: Paulo Lima | N36: Troca de posicionamento da presilha | O36: sem impacto
A37: =YEAR(L37) -> 1900 | B37: =WEEKNUM(I37) -> 52 | C37: =WEEKNUM(L37) -> 0 | E37: CR-0115594-00 | G37: GEM | H37: Marcelo | I37: 44552 | J37: 0.48333333 | K37: Paulo Lima | N37: Troca do tubo liso de E12128600 para E14165400 | O37: Sem necessidade de investimento
A38: =YEAR(L38) -> 1900 | B38: =WEEKNUM(I38) -> 52 | C38: =WEEKNUM(L38) -> 0 | E38: CR-0116167-00 | G38: VS30 | H38: Márcio Pericles Militani | I38: 44551 | J38: 0.65763889 | K38: Paulo Lima | N38: Novo Chicote da bomba do limpador do parabrisa. | O38: Necessidade de 02 miniaplicadores para o terminal 32025Y1G5 e 32025Y1G6
A39: =YEAR(L39) -> 2022 | B39: =WEEKNUM(I39) -> 51 | C39: =WEEKNUM(L39) -> 2 | E39: CR-0115838-00 | G39: VS30 | H39: Márcio Pericles Militani | I39: 44546 | J39: 0.69305556 | K39: Marcelo Santos | L39: 44564 | M39: 0.45763889 | N39: Sem impacto par corte e Lead prep. analise feita base WLL , entrando 4 circuitos diretos novos.
A40: =YEAR(L40) -> 2022 | B40: =WEEKNUM(I40) -> 51 | C40: =WEEKNUM(L40) -> 2 | E40: CR-0115976-00 | G40: VS30 | H40: Márcio Pericles Militani | I40: 44546 | J40: 0.70208333 | K40: Marcelo Santos | L40: 44564 | M40: 0.475 | N40: Sem impacto para corte e Lead prep.Alteração do cabo 16AC12020 Para E25180500 no SAP para adequação da unidade de medida.
...

Sheet Prioridades resposta
A1: prioricade | B1: Programa | C1: Status Planta | D1: CR # | E1: Data Submissão SEM | F1: Envio da CR p/ análise | G1: Fase | H1: MY | I1: Nº Doc | J1: CR "On Hold"? | K1: Status Cotações | L1: Status Produto | M1: Status Processos | N1: Status Meios Montagem | O1: Status Teste Elétrico | P1: Status Corte & Lead Prep | Q1: Status Qualidade | R1: Dias com Eng. Cotações
B2: GEM | C2: Pendente | D2: CR-0183330-00 | E2: 45449 | F2: 45449 | H2: 2025 | I2: Não | J2: Não | K2: OK | L2: OK | M2: OK | N2: OK | O2: OK | P2: OK | Q2: LATE | R2: 24 | S2: =VLOOKUP(D2,'Controle de CR'!E:E,1,0) -> CR-0183330-00
B3: SPIN | C3: Pendente | D3: CR-0185339-00 | E3: 45477 | F3: 45477 | H3: 2025 | I3: Não | J3: Não | K3: OK | L3: OK | M3: OK | N3: OK | O3: OK | P3: LATE | Q3: LATE | R3: 13 | S3: =VLOOKUP(D3,'Controle de CR'!E:E,1,0) -> CR-0185339-00
B4: SPIN | C4: Pendente | D4: CR-0185493-00 | E4: 45481 | F4: 45481 | H4: 2025 | I4: Não | J4: Não | K4: OK | L4: N/A | M4: OK | N4: OK | O4: OK | P4: LATE | Q4: LATE | R4: 8 | S4: =VLOOKUP(D4,'Controle de CR'!E:E,1,0) -> CR-0185493-00
B5: VS30 | C5: Pendente | D5: CR-0190308-00 | E5: 45488 | F5: 45488 | H5: 2024_1 | I5: Não | J5: Não | K5: OK | L5: N/A | M5: OK | N5: OK | O5: OK | P5: LATE | Q5: LATE | R5: 6 | S5: =VLOOKUP(D5,'Controle de CR'!E:E,1,0) -> CR-0190308-00
B6: VS30 | C6: Pendente | D6: CR-0190391-00 | E6: 45490 | F6: 45490 | H6: 2024_1 | I6: Não | J6: Não | K6: OK | L6: OK | M6: ON TIME | N6: OK | O6: OK | P6: ON TIME | Q6: ON TIME | R6: 3 | S6: =VLOOKUP(D6,'Controle de CR'!E:E,1,0) -> CR-0190391-00

Sheet My23.2Vs30
A1: Ano | B1: Recebida Week | C1: Respondida Week | D1: DCN | E1: CR | F1: IP | G1: Projeto | H1: Nome Resp. CR | I1: Data | J1: Hora | K1: Avaliado | L1: Data | M1: Hora | N1: EQUIPAMENTO | O1: LEAD TIME | P1: Restrição | Q1: OBSERVAÇÃO | R1: Inicio do processo | S1: envio de DT e VT | T1: Liberação | U1: Nº RC | V1: Nº PO | W1: APORVAÇÃO DE DT e VT | X1: REQUISIÇÃO | Y1: PO | Z1: DATA DE CEGADA | AA1: VALIDAÇÃO | AB1: APROVAÇÃO DA VALIDAÇÃO | AC1: ENVIO PARA QUALIDADE | AD1: Data de Entrega
E2: CR-0161055-00 | F2: VS30 – SORP – 2023_02 Família: IP WH Tipo: Release Número: VAT2523 | G2: VS30 | H2: Militani, Marcio Pericles | I2: 45156 | J2: 0.35833333 | K2: Marcelo Santos | L2: 45174 | M2: 0.67222222 | N2: Aplicadores | O2: 70 | P2: NOVO | Q2: Aplicador para terminal E09996900 ( 927829-5 ) | R2: =AD2-O2 -> 45203 | S2: enviado para aprovação dia quar 13/12/2023 13:04 | T2: liberado pela Aline dia qua 13/12/2023 15:02 | AD2: 45273
E3: CR-0161055-00 | F3: VS30 – SORP – 2023_02 Família: IP WH Tipo: Release Número: VAT2523 | G3: VS30 | H3: Militani, Marcio Pericles | I3: 45156 | J3: 0.35833333 | K3: Marcelo Santos | L3: 45174 | M3: 0.67222222 | N3: Validações | O3: 60 | P3: NOVO | Q3: 1 validação de terminais E09996900 conforme Norma VS30. | R3: =AD3-O3 -> 45213 | AD3: 45273
E4: CR-0161055-00 | F4: VS30 – SORP – 2023_02 Família: IP WH Tipo: Release Número: VAT2523 | G4: VS30 | H4: Militani, Marcio Pericles | I4: 45156 | J4: 0.35833333 | K4: Marcelo Santos | L4: 45174 | M4: 0.67222222 | N4: Aplicadores | O4: 70 | P4: NOVO | Q4: 1 Aplicador para Terminal Splice CLIP E40086800 | R4: =AD4-O4 -> 45275 | S4: OK | W4: Aprovado para o terminal E40086800 (11/12/2023 às 09:11) | AD4: 45345
A5: 2023 | B5: 33 | C5: 36 | E5: CR-0161055-00 | F5: VS30 – SORP – 2023_02 Família: IP WH Tipo: Release Número: VAT2523 | G5: VS30 | H5: Militani, Marcio Pericles | I5: 45156 | J5: 0.35833333 | K5: Marcelo Santos | L5: 45174 | M5: 0.67222222 | N5: Validações | O5: 60 | P5: NOVO | Q5: 1 validação de terminais Splice CLIP E40086800 Norma VS30. | R5: =AD5-O5 -> 45285 | AD5: 45345
E6: CR-0161055-00 | F6: VS30 – SORP – 2023_02 Família: IP WH Tipo: Release Número: VAT2523 | G6: VS30 | H6: Militani, Marcio Pericles | I6: 45156 | J6: 0.35833333 | K6: Marcelo Santos | L6: 45174 | M6: 0.67222222 | N6: Prensa | O6: 90 | P6: Retrofit CAM | Q6: 1 Prensa mecal de 4 Toneladas com adequação NR12 para Aplicação Terminal Splice CLIP E40086800 (SPLC CLIP,Cu CORE,Sn PLT,390275) | R6: =AD6-O6 -> 45255 | S6: enviado para aprovação dia quar 13/12/2023 13:04 | AD6: 45345
E7: CR-0161082-00 | F7: CR-0161082-00 - Body | G7: VS30 | H7: Militani, Marcio Pericles | I7: 45177 | J7: 0.68472222 | K7: Marcelo Santos | L7: 45183 | M7: 0.75902778 | N7: Aplicadores | O7: 70 | P7: DUPLICAÇÃO | Q7: 1 aplicador TE para terminal E03732200 ( diversidade de Circuitos ) | R7: =AD7-O7 -> 45275 | S7: enviado para aprovação dia quar 13/12/2023 13:04 | T7: liberado pela Aline dia qua 13/12/2023 15:02 | AD7: 45345
E8: CR-0161082-00 | F8: CR-0161082-00 - Body | G8: VS30 | H8: Militani, Marcio Pericles | I8: 45177 | J8: 0.68472222 | K8: Marcelo Santos | L8: 45183 | M8: 0.75902778 | N8: Aplicadores | O8: 70 | P8: DUPLICAÇÃO | Q8: 1 aplicador TE para terminal 3202581Z7 ( diversidade de Circuitos ) | R8: =AD8-O8 -> 45275 | S8: enviado para aprovação dia quar 13/12/2023 13:04 | T8: liberado pela Aline dia qua 13/12/2023 15:02 | AD8: 45345
E9: CR-0161082-00 | F9: CR-0161082-00 - Body | G9: VS30 | H9: Militani, Marcio Pericles | I9: 45177 | J9: 0.68472222 | K9: Marcelo Santos | L9: 45183 | M9: 0.75902778 | N9: Aplicadores | O9: 70 | P9: DUPLICAÇÃO | Q9: 1 aplicador TE para terminal E04004100 ( diversidade de Circuitos ) | R9: =AD9-O9 -> 45275 | S9: enviado para aprovação dia quar 13/12/2023 13:04 | T9: liberado pela Aline dia qua 13/12/2023 15:02 | AD9: 45345
E10: CR-0161082-00 | F10: CR-0161082-00 - Body | G10: VS30 | H10: Militani, Marcio Pericles | I10: 45177 | J10: 0.68472222 | K10: Marcelo Santos | L10: 45183 | M10: 0.75902778 | N10: Aplicadores | O10: 70 | P10: DUPLICAÇÃO | Q10: 1 aplicador TE para terminal E04848200 ( diversidade de Circuitos ) | R10: =AD10-O10 -> 45275 | S10: enviado para aprovação dia quar 13/12/2023 13:04 | T10: liberado pela Aline dia qua 13/12/2023 15:02 | AD10: 45345
A11: 2023 | B11: 34 | C11: 37 | E11: CR-0161091-00 | F11: Projeto: VS30 – SORP – 2023_02 Família: BODY Tipo: Release Número: VAT2623 | G11: VS30 | H11: Militani, Marcio Pericles | I11: 45159 | J11: 0.58194444 | K11: Marcelo Santos | L11: 45184 | M11: 0.3875 | N11: N/A | O11: 30 | P11: - | Q11: Sem impacto para corte e Lead Prep. Condicionado ao investimentos reportado na CR-0161082-00. | R11: =AD11-O11 -> -30
A12: 2023 | B12: 34 | C12: 37 | E12: CR-0161100-00 | F12: VS30 – SORP – 2023_02 Família: BODY Tipo: Release Número: VAT2623 | G12: VS30 | H12: Militani, Marcio Pericles | I12: 45159 | J12: 0.58541667 | K12: Marcelo Santos | L12: 45184 | M12: 0.38958333 | N12: N/A | O12: 30 | P12: - | Q12: Sem impacto para corte e Lead Prep. Condicionado ao investimentos reportado na CR-0161082-00. | R12: =AD12-O12 -> -30
A13: 2023 | B13: 34 | C13: 37 | E13: CR-0161150-00 | F13: VS30 – SORP – 2023_02 Família: BODY Tipo: Release Número: VAT2623 | G13: VS30 | H13: Militani, Marcio Pericles | I13: 45159 | J13: 0.71875 | K13: Marcelo Santos | L13: 45184 | M13: 0.39097222 | N13: N/A | O13: 30 | P13: - | Q13: Sem impacto para corte e Lead Prep. Condicionado ao investimentos reportado na CR-0161082-00. | R13: =AD13-O13 -> -30
A14: 2023 | B14: 34 | C14: 37 | E14: CR-0161274-00 | F14: VS30 – SORP – 2023_02 Família: BODY Tipo: Release Número: VAT2623 | G14: VS30 | H14: Militani, Marcio Pericles | I14: 45160 | J14: 0.70347222 | K14: Marcelo Santos | L14: 45184 | M14: 0.39236111 | N14: N/A | O14: 30 | P14: - | Q14: Sem impacto para corte e Lead Prep. Condicionado ao investimentos reportado na CR-0161082-00. | R14: =AD14-O14 -> -30
A15: 2023 | B15: 34 | C15: 37 | E15: CR-0161281-00 | F15: VS30 – SORP – 2023_02 Família: BODY Tipo: Release Número: VAT2623 | G15: VS30 | H15: Militani, Marcio Pericles | I15: 45162 | J15: 0.41180556 | K15: Marcelo Santos | L15: 45184 | M15: 0.39583333 | N15: N/A | O15: 30 | P15: - | Q15: Sem impacto para corte e Lead Prep. Condicionado ao investimentos reportado na CR-0161082-00. | R15: =AD15-O15 -> -30
A16: 2023 | B16: 34 | C16: 37 | E16: CR-0161391-00 | F16: VS30 – SORP – 2023_02 Família: BODY Tipo: Release Número: VAT2623 | G16: VS30 | H16: Militani, Marcio Pericles | I16: 45162 | J16: 0.39166667 | K16: Marcelo Santos | L16: 45184 | M16: 0.39861111 | N16: N/A | O16: 30 | P16: - | Q16: Sem impacto para corte e Lead Prep. Condicionado ao investimentos reportado na CR-0161082-00. | R16: =AD16-O16 -> -30
A17: 2023 | B17: 35 | C17: 37 | E17: CR-0161685-00 | F17: VS30 – SORP – 2023_02 Família: BODY Tipo: Release Número: VAT2623 | G17: VS30 | H17: Militani, Marcio Pericles | I17: 45170 | J17: 0.69930556 | K17: Marcelo Santos | L17: 45184 | M17: 0.4 | N17: N/A | O17: 30 | P17: - | Q17: Sem impacto para corte e Lead Prep. Condicionado ao investimentos reportado na CR-0161082-00. | R17: =AD17-O17 -> -30
A18: 2023 | B18: 35 | C18: 37 | E18: CR-0162023-00 | F18: VS30 – SORP – 2023_02 Família: BODY Tipo: Release Número: VAT2623 | G18: VS30 | H18: Militani, Marcio Pericles | I18: 45170 | J18: 0.71180556 | K18: Marcelo Santos | L18: 45184 | M18: 0.40138889 | N18: N/A | O18: 30 | P18: - | Q18: Sem impacto para corte e Lead Prep. Condicionado ao investimentos reportado na CR-0161082-00. | R18: =AD18-O18 -> -30
A19: 2023 | B19: 36 | C19: 37 | E19: CR-0161685-01 | F19: VS30 – SORP – 2023_02 Família: BODY Tipo: Release Número: VAT2623 | G19: VS30 | H19: Militani, Marcio Pericles | I19: 45177 | J19: 0.67569444 | K19: Marcelo Santos | L19: 45184 | M19: 0.40347222 | N19: N/A | O19: 30 | P19: - | Q19: Sem impacto para corte e Lead Prep. Condicionado ao investimentos reportado na CR-0161082-00. | R19: =AD19-O19 -> -30
A20: 2023 | B20: 37 | C20: 37 | E20: CR-0162605-00 | F20: VS30 – SORP – 2023_02 Família: BODY Tipo: Release Número: VAT2623 | G20: VS30 | H20: Militani, Marcio Pericles | I20: 45180 | J20: 0.66944444 | K20: Marcelo Santos | L20: 45184 | M20: 0.40486111 | N20: N/A | O20: 30 | P20: - | Q20: Sem impacto para corte e Lead Prep. Condicionado ao investimentos reportado na CR-0161082-00. | R20: =AD20-O20 -> -30
A21: 2023 | B21: 35 | C21: 37 | E21: CR-0161852-00 | F21: VS30 – SORP – 2023_02 Família: BODY Tipo: PFD Número: PFD-VS30-BR907-AEHJ2023_02-2438w | G21: VS30 | H21: Militani, Marcio Pericles | I21: 45169 | J21: 0.42152778 | K21: Marcelo Santos | L21: 45184 | N21: N/A | O21: 30 | P21: - | Q21: Considerar sem impacto para corte e Lead Prep. Scrap R$ 1.667,87 | R21: =AD21-O21 -> -30
A22: 2023 | B22: 35 | C22: 37 | E22: CR-0161862-00 | F22: VS30 – SORP – 2023_02 Família: BODY Tipo: PFD Número: PFD-VS30-BR907-AEHJ2023_02-2437w | G22: VS30 | H22: Militani, Marcio Pericles | I22: 45169 | J22: 0.42430556 | K22: Marcelo Santos | L22: 45184 | M22: 0.5875 | N22: N/A | O22: 30 | P22: - | Q22: Considerar sem impacto para corte e Lead Prep. | R22: =AD22-O22 -> -30
E23: CR-0161082-00 | F23: CR-0161082-00 - Body | G23: VS30 | H23: Militani, Marcio Pericles | I23: 45177 | J23: 0.68472222 | K23: Marcelo Santos | L23: 45183 | M23: 0.75902778 | O23: 30 | P23: - | Q23: 2 caixas de Poleaseal | R23: =AD23-O23 -> -30
A24: 2023 | B24: 34 | C24: 36 | E24: CR-0161083-00 | F24: BODY Tipo: Release Número: VAT2623 | G24: VS30 | H24: Militani, Marcio Pericles | I24: 45159 | J24: 0.56805556 | K24: Marcelo Santos | L24: 45174 | M24: 0.38055556 | O24: 30 | P24: - | Q24: Considerar sem impacto para corte e Lead Prep. Scrap R$ 954,68 | R24: =AD24-O24 -> -30 | S24: N/A | W24: N/A | X24: N/A
A25: 2023 | B25: 36 | C25: 37 | E25: CR-0161082-00 | F25: CR-0161082-00 - Body | G25: VS30 | H25: Militani, Marcio Pericles | I25: 45177 | J25: 0.68472222 | K25: Marcelo Santos | L25: 45183 | M25: 0.75902778 | O25: 30 | P25: - | Q25: 8 rolos de dupla Face | R25: =AD25-O25 -> -30
A26: 2023 | B26: 35 | C26: 37 | E26: CR-0161865-00 | F26: VS30 – SORP – 2023_02 Família: BODY Tipo: PFD Número: PFD-VS30-BR907-AEHJ2023_02-2435w | G26: VS30 | H26: Militani, Marcio Pericles | I26: 45169 | J26: 0.42708333 | K26: Marcelo Santos | L26: 45184 | M26: 0.59583333 | O26: 30 | Q26: Sem impacto para corte e Lead prep. Considerar apenas Scrap devido alteração de comprimento Scrap R$ R$ 1.327,11 | R26: =AD26-O26 -> -30
A27: 2023 | B27: 38 | C27: 39 | E27: CR-0163101-00 | F27: VS30 – SORP – 2023_02 Família: IP WH Tipo: PFD Número: PFD-VS30-BR907-AEHJ2023_02-2433w | G27: VS30 | H27: Militani, Marcio Pericles | I27: 45188 | J27: 0.34444444 | K27: Marcelo Santos | L27: 45197 | M27: 0.73819444 | N27: Equipamento | O27: 90 | P27: DUPLICAÇÃO | Q27: 1 máquina de decape (Komax MIRA ) aproximadamente R$56.500,00 ( investimento necessário para garantir corte do dreno e do cabo marrom no comprimento correto vide anexo ) Scrap. R$ 623,00 | R27: =AD27-O27 -> -90
A28: 2023 | B28: 42 | C28: 43 | E28: CR-0164538-01 | F28: VS30 – SORP – 2023_02 Família: BODY Tipo: PFD Número: PFD-VS30-BR907-AEHJ2023_02-2518 | G28: VS30 | H28: Militani, Marcio Pericles | I28: 45215 | J28: 0.41319444 | K28: Marcelo Santos | L28: 45222 | M28: 0.77013889 | N28: Aplicadores | O28: 70 | P28: DUPLICAÇÃO | Q28: 1 aplicador TE para terminal E00309500.( para uso no lead Prep. Seal Crimp ) Lead Time após liberação da Verba. 78 dias | R28: =AD28-O28 -> -70 | S28: enviado para cotação dia 11/12/2023 às 13:35 h.
A29: 2023 | B29: 42 | C29: 43 | E29: CR-0165462-00 | F29: VS30 – SORP – 2023_02 Família: BODY Tipo: PFD Número: PFD-VS30-BR907-AEHJ2023_02-2434w | G29: VS30 | H29: Militani, Marcio Pericles | I29: 45215 | J29: 0.41597222 | K29: Marcelo Santos | L29: 45224 | M29: 0.62222222 | N29: N/A | Q29: Considerar sem impacto para corte e lead Prep.( Analise feita Base delta Cut disponibilizado.) Alteração comprimento dos Circuitos novos MC7301B, 7404B e 7405B VS30 – SORP – 2023_02. | R29: =AD29-O29 -> 0
A30: 2023 | B30: 43 | C30: 45 | E30: CR-0166091-00 | F30: VS30 – SORP – 2023_02 Família: BODY Tipo: PFD Número: PFD-VS30-BR907-AEHJ2023_02-2533 | G30: VS30 | H30: Militani, Marcio Pericles | I30: 45224 | J30: 0.58958333 | K30: Marcelo Santos | L30: 45241 | M30: 0.31388889 | N30: N/A | Q30: Considerar sem impacto para corte e Lead Prep. Analise feita base documentos fornecido na CR, PFD-VS30-BR907-AEHJ2023_02-2533_LU, BOM-COMPARISON_A9070014899_B04_10107 e DELTA-LABOR-R_A9070014899_B04_10107. | R30: =AD30-O30 -> 0
A31: 2023 | B31: 43 | C31: 45 | E31: CR-0166250-00 | F31: VS30 – SORP – 2023_02 Família: IP WH Tipo: PFD Número: PFD-VS30-BR907-AEHJ2023_02-2533 Assunto: 1. VS30 - WIRING HARNESS IP , 2. PFD-VS30-BR907-AEHJ2023_02-2500 | G31: VS30 | H31: Militani, Marcio Pericles | I31: 45224 | J31: 0.59305556 | K31: Marcelo Santos | L31: 45241 | M31: 0.40416667 | N31: N/A | Q31: Considerar Sem impacto par corte e lead Prep. Analise feita base documentação disponibilizado na CR, BOM-COMPARISON_A9070011599_B05_10120, PFD-VS30-BR907-AEHJ2023_02-2500_LU e DELTA-LABOR_A9070011599_B05_10120 | R31: =AD31-O31 -> 0
A32: 2023 | B32: 43 | C32: 45 | E32: CR-0166494-00 | F32: VS30 – SORP – 2023_02 Família: IP WH Tipo: Issue Número: NA | G32: VS30 | H32: Militani, Marcio Pericles | I32: 45225 | J32: 0.60416667 | K32: Marcelo Santos | L32: 45241 | N32: Validações | O32: 60 | Q32: 1 Validação de crimpagem conforme Norma VS30. conforme informação O fornecedor estou considerando que vamos utilizar mesmo aplicador do terminal 32025YFU. Mesmo Aplicador | R32: =AD32-O32 -> -60
E33: CR-0165593-00 | F33: VS30 – SORP – 2023_02 Família: BODY Tipo: Release Número: VAT2623 Assunto: 1. Release of new | G33: vS30 | H33: Militani, Marcio Pericles | I33: 45240 | J33: 0.51736111 | K33: Marcelo Santos | L33: 45261 | M33: 0.51805556 | N33: Aplicadores | O33: 70 | P33: DUPLICAÇÃO | Q33: 1 aplicador TE para terminal E03355600. ( Será Usado No Lead Prep. necessário devido conflito entre os processos de Corte e lead Prep.) | R33: =AD33-O33 -> -70 | S33: enviado para cotação dia 11/12/2023 às 13:35 h.
E34: CR-0165593-00 | F34: VS30 – SORP – 2023_02 Família: BODY Tipo: Release Número: VAT2623 Assunto: 1. Release of new | G34: vS30 | H34: Militani, Marcio Pericles | I34: 45240 | J34: 0.51736111 | K34: Marcelo Santos | L34: 45261 | M34: 0.51805556 | N34: Aplicadores | O34: 70 | P34: DUPLICAÇÃO | Q34: 1 aplicador TE para terminal E03999200. ( Será Usado No Lead Prep. necessário devido conflito entre os processos de Corte e lead Prep.) | R34: =AD34-O34 -> -70 | S34: enviado para cotação dia 11/12/2023 às 13:35 h.
E35: CR-0165593-00 | F35: VS30 – SORP – 2023_02 Família: BODY Tipo: Release Número: VAT2623 Assunto: 1. Release of new | G35: vS30 | H35: Militani, Marcio Pericles | I35: 45240 | J35: 0.51736111 | K35: Marcelo Santos | L35: 45261 | M35: 0.51805556 | N35: Aplicadores | O35: 70 | P35: DUPLICAÇÃO | Q35: 1 aplicador TE para terminal E04004100. ( Usado no dois lados dos circuitos temos apenas 1 Aplicador ) | R35: =AD35-O35 -> -70 | S35: enviado para cotação dia 11/12/2023 às 13:35 h.
E36: CR-0165593-00 | F36: VS30 – SORP – 2023_02 Família: BODY Tipo: Release Número: VAT2623 Assunto: 1. Release of new | G36: vS30 | H36: Militani, Marcio Pericles | I36: 45240 | J36: 0.51736111 | K36: Marcelo Santos | L36: 45261 | M36: 0.51805556 | N36: Aplicadores | O36: 70 | P36: DUPLICAÇÃO | Q36: 1 Aplicador TE para terminal E04848200. ( Devido Acréscimo de circuitos acima de 8.000mm será distribuído para Maquina Coiler CC64 ) | R36: =AD36-O36 -> -70 | S36: enviado para cotação dia 11/12/2023 às 13:35 h.
E37: CR-0165593-00 | F37: VS30 – SORP – 2023_02 Família: BODY Tipo: Release Número: VAT2623 Assunto: 1. Release of new | G37: vS30 | H37: Militani, Marcio Pericles | I37: 45240 | J37: 0.51736111 | K37: Marcelo Santos | L37: 45261 | M37: 0.51805556 | N37: N/A | Q37: 1 caixa de Polaseal | R37: =AD37-O37 -> 0
E38: CR-0165593-00 | F38: VS30 – SORP – 2023_02 Família: BODY Tipo: Release Número: VAT2623 Assunto: 1. Release of new | G38: vS30 | H38: Militani, Marcio Pericles | I38: 45240 | J38: 0.51736111 | K38: Marcelo Santos | L38: 45261 | M38: 0.51805556 | N38: N/A | Q38: 1 rolo de papel contact. | R38: =AD38-O38 -> 0
A39: 2023 | B39: 45 | C39: 48 | E39: CR-0165593-00 | F39: VS30 – SORP – 2023_02 Família: BODY Tipo: Release Número: VAT2623 Assunto: 1. Release of new | G39: vS30 | H39: Militani, Marcio Pericles | I39: 45240 | J39: 0.51736111 | K39: Marcelo Santos | L39: 45261 | M39: 0.51805556 | N39: N/A | Q39: 1 rolo de Dupla Face | R39: =AD39-O39 -> 0
A40: 2023 | B40: 46 | C40: 49 | E40: CR-0167911-00 | F40: VS30 – SORP – 2023_02 Família: IP WH Tipo: Release Número: VAT2523 | G40: VS30 | H40: Militani, Marcio Pericles | I40: 45246 | J40: 0.68125 | K40: Marcelo Santos | L40: 45268 | M40: 0.60347222 | N40: N/A | Q40: Considerar sem impacto para corte e Lead Prep. | R40: =AD40-O40 -> 0

Sheet Aplicadores MY26
C2: Aplicadores/calhas | D2: Disponivel | E2: Maqs GEM | F2: Carga hrs Gem | G2: Voume dia | H2: Delta | I2: Compra | J2: MY
C3: 32025Y2XV | D3: 0 | E3: 2 | F3: 2.0867029 | G3: 6644.7276 | H3: -2 | I3: 1 | K3: CR-0171416-00 BODY CARBON | M3: CR-0166437-01 BODY | N3: Não Pedir carbon
C4: E04648500 | D4: 0 | E4: 2 | F4: 1.1342066 | G4: 3151.7668 | H4: -2 | I4: 1 | K4: CR-0171416-00 BODY CARBON
C5: E00166100 | D5: 0 | E5: 3 | F5: 1.3960154 | G5: 2410.0197 | H5: -3 | I5: 1 | K5: CR-0171416-00 BODY CARBON | M5: CR-0166437-01 BODY | N5: Não Pedir
C6: E00020633 | D6: 0 | E6: 3 | F6: 0.82667419 | G6: 1493.4207 | H6: -3 | I6: 1 | K6: CR-0171416-00 BODY CARBON | M6: CR-0166437-01 BODY | N6: Não Pedir
C7: 320298235 | D7: 1 | E7: 2 | F7: 0.34074897 | G7: 1192.9199 | H7: -1 | I7: 1 | K7: CR-0171416-00 BODY CARBON | L7: Obsoleto desmontado
C8: E01080600 | D8: 0 | E8: 0 | F8: 0 | G8: 0 | H8: 0 | I8: 1 | K8: CR-0171595-00 IP HARNESS carbon
C9: E05869700 | D9: 0 | E9: 0 | F9: 0 | G9: 0 | H9: 0 | I9: 1 | K9: CR-0171595-00 IP HARNESS carbon
C10: 320298243 | D10: 1 | E10: 0 | F10: 0 | G10: 0 | H10: 1 | I10: 1 | K10: CR-0171595-00 IP HARNESS carbon
C11: 32025Y19G | D11: 0 | E11: 0 | F11: 0 | G11: 5400 | H11: 0 | I11: 1 | K11: CR-0171595-00 IP HARNESS carbon | L11: Desmontado
C12: E27713500 | D12: 0 | E12: =VLOOKUP(C12,'[1]Distr.Aplicadores GEM'!$A:$B,2,0) -> 0 | F12: =VLOOKUP(C12,'[1]Distr.Aplicadores GEM'!$A:$H,8,0) -> 0 | G12: 2244.7614 | H12: =D12-E12 -> 0 | I12: 1 | K12: CR-0171785-01 Rear Lamp Carbon | M12: CR-0162211-00 IP | N12: Não Pedir
C13: E27713500 | D13: 0 | E13: 1 | F13: 0.6393524 | G13: 2244.7614 | H13: -1 | I13: 1 | K13: CR-0171817-01 Liftgate Carbon | M13: CR-0162211-00 IP | N13: Não Pedir
C14: 3202563E7 | D14: 0 | E14: 1 | G14: 0 | H14: -1 | I14: 1 | K14: CR-0171817-01 Liftgate Carbon
C15: E16318100 | D15: 2 | E15: 4 | F15: 7.0213813 | G15: 15940 | H15: -2 | I15: 1 | K15: CR-0172035-00 Liftgate Ext CARBON
C16: E00006853 | D16: 0 | E16: 0 | F16: 0 | G16: 0 | H16: 0 | I16: 1 | K16: CR-0172035-00 Liftgate Ext CARBON
C17: E16491700 | D17: 0 | E17: 0 | F17: 0 | G17: 0 | H17: 0 | I17: 1 | K17: CR-0172035-00 Liftgate Ext CARBON
C18: 3202535K9 | D18: 0 | E18: 0 | F18: 0 | G18: 0 | H18: 0 | I18: 1 | K18: CR-0172035-00 Liftgate Ext CARBON
C19: 32025Y1CW | D19: 0 | E19: 0 | F19: 0 | G19: 0 | H19: 0 | I19: 1 | K19: CR-0172035-00 Liftgate Ext CARBON
C20: 32025Y20B | D20: 0 | E20: 0 | F20: 0 | G20: 0 | H20: 0 | I20: 1 | K20: CR-0172352-00 Front Bumper Carbon
C21: 3202501G8 | D21: 0 | E21: 0 | F21: 0 | G21: 0 | H21: 0 | I21: 1 | J21: 2026 | K21: CR-0162211-00 IP
C22: E32673300 | D22: 0 | E22: 0 | F22: 0 | G22: 0 | H22: 0 | I22: 1 | J22: 2026 | K22: CR-0162211-00 IP
C23: 32025Y36A | D23: 0 | E23: 0 | F23: 0 | G23: 0 | H23: 0 | I23: 1 | J23: 2026 | K23: CR-0162211-00 IP
C24: E27713500 | D24: 0 | E24: 0 | F24: 0 | G24: 0 | H24: 0 | I24: 1 | J24: 2026 | K24: CR-0162211-00 IP
C25: 3204505B1 | D25: 0 | E25: 0 | F25: 0 | G25: 0 | H25: 0 | I25: 5 | J25: 2026 | K25: CR-0166437-01 BODY
C26: 320452329 | D26: 0 | E26: 0 | F26: 0 | G26: 0 | H26: 0 | I26: 1 | J26: 2026 | K26: CR-0166437-01 BODY
C27: 320455AKQ | D27: 0 | E27: 0 | F27: 0 | G27: 0 | H27: 0 | I27: 1 | J27: 2026 | K27: CR-0166437-01 BODY
C28: E37621700 | D28: 0 | E28: 0 | F28: 0 | G28: 0 | H28: 0 | I28: 1 | J28: 2026 | K28: CR-0166437-01 BODY
C29: E00020633 | D29: 0 | E29: 0 | F29: 0 | G29: 0 | H29: 0 | I29: 1 | J29: 2026 | K29: CR-0166437-01 BODY
C30: E00166100 | D30: 0 | E30: 0 | F30: 0 | G30: 0 | H30: 0 | I30: 1 | J30: 2026 | K30: CR-0166437-01 BODY
C31: 3202502F9 | D31: 0 | E31: 0 | F31: 0 | G31: 0 | H31: 0 | I31: 1 | J31: 2026 | K31: CR-0166437-01 BODY
C32: 320263VT6 | D32: 0 | E32: 0 | F32: 0 | G32: 0 | H32: 0 | I32: 1 | J32: 2026 | K32: CR-0166437-01 BODY
C33: 32025Y2XV | D33: 0 | E33: 0 | F33: 0 | G33: 0 | H33: 0 | I33: 1 | J33: 2026 | K33: CR-0166437-01 BODY
C34: 3299571G9 | K34: CR-0171416-00 BODY CARBON
C35: 320452329 | K35: CR-0171416-00 BODY CARBON | L35: CR-0166437-01 BODY | N35: Não Pedir
C36: E10690000 | K36: CR-0172035-00 Liftgate Ext | N36: Não Pedir
C37: 320455A8X | K37: CR-0172352-00 Front Bumper Carbon

Sheet CR MY26
B1: CR # | C1: Fase | D1: Nº Doc | E1: Envio da CR p/ análise | G1: CR "On Hold"?
B2: CR-0160280-00 | C2: MVBs | D2: 4489010 | E2: 45148 | F2: Afeta somente teste eletrico não foi respondido por corte e lead Prep. | G2: Sim | H2: GEM
B3: CR-0160595-00 | C3: MVBs | D3: EWO 4489010 | E3: 45169 | F3: Sem impacto para corte e Lead Prep.( analise feita base Delta CutSheet e BOM Scrap R$ 18.744,40 Alteração de comprimento de circuitos e tubos | G3: Não | H3: GEM
B4: CR-0161022-00 | C4: MVBs | D4: EWO 4489010 | E4: 45169 | F4: Sem impacto para corte e Lead Prep.( analise feita base Delta CutSheet e BOM Scrap R$ 17.489,97 Alteração de comprimento de circuitos e tubos | G4: Não | H4: GEM
B5: CR-0161020-00 | C5: MVBs | D5: EWO 4489010 | E5: 45169 | F5: Sem impacto para corte e Lead Prep.( analise feita base Delta CutSheet e BOM ) Scrap R$ 10.795,34 | G5: Não | H5: GEM
B6: CR-0161019-01 | C6: MVBs | D6: EWO 4489010 | E6: 45169 | F6: Sem impacto para corte e Lead Prep.( analise feita base Delta CutSheet e BOM ) Scrap R$ 10.795,21 CR cancelada | G6: Não | H6: GEM
B7: CR-0161953-00 | C7: MVBs | D7: 4489010 | E7: 45170 | F7: Sem impacto para corte e Lead Prep.( analise feita base Delta CutSheet e BOM ) Scrap R$ 1.382,86 | G7: Não | H7: GEM
B8: CR-0161952-00 | C8: MVBs | D8: 4489010 | E8: 45173 | F8: Sem impacto para corte e Lead Prep.( analise feita base Delta CutSheet e BOM ) Scrap R$ 1.100,34 | G8: Não | H8: GEM
B9: CR-0160595-01 | C9: MVBs | D9: EWO 4489010 | E9: 45202 | F9: Considerar para corte Lead Prep.( Analise feita base Delta Cut Sheet e Delta BOM ) 1 validação conforme Norma GMW17136 para Termo retrátil E02000700 R$ 31.731,33 Scrap Alteração de comprimento considerado 1 dia de lote para Scrap. | G9: Não | H9: GEM
B10: CR-0161019-02 | C10: MVBs | D10: EWO 4489010 | E10: 45202 | F10: #N/A | G10: Não | H10: GEM
B11: CR-0161020-01 | C11: APPV | D11: EWO#4489010 | E11: 45202 | F11: #N/A | G11: Não | H11: GEM
B12: CR-0161022-01 | C12: APPV | D12: EWO 4489010 | E12: 45202 | F12: #N/A | G12: Não | H12: GEM
B13: CR-0162419-00 | C13: APPV | D13: EWO 4489010 | E13: 45212 | F13: #N/A | G13: Não | H13: GEM
B14: CR-0165674-00 | C14: APPV | D14: EWO 4489010 | E14: 45217 | F14: CR CANCELADA | G14: Não | H14: GEM
B15: CR-0165673-00 | C15: APPV | D15: EWO#4489010 | E15: 45217 | F15: #N/A | G15: Não | H15: GEM
B16: CR-0162419-01 | C16: APPV | D16: EWO 4489010 | E16: 45217 | F16: Considerar para Corte e Lead Prep.( implementação condicionado a aprovação das validações conforme Norma GMW 17136 e USCAR 45 ) 1 validações conforme norma GMW17136. 1 validações conforme norma USCAR45. Scrap R$ 5.488,16 16 horas técnicas Necessidade de 150 peças do termo retrátil E02000700 para confecção das amostras para validação. Lead time para Validações e implementação a partir da liberação da verba 83dias | G16: Sim | H16: GEM
B17: CR-0162423-00 | C17: APPV | D17: EWO#4489010 | E17: 45217 | F17: Considerar sem Impacto para Corte e Lead Prep.( Analise realizada base delta Cutsheet 52183579_003 disponibilizado na CR-0162423-00 ) Scrap R$ 6.204,58 | G17: Sim | H17: GEM
B18: CR-0160595-02 | C18: APPV | D18: EWO 4489010 | E18: 45217 | F18: Considerar para corte Lead Prep.( Analise feita base Delta Cut Sheet e Delta BOM, implementação condicionada aos testes e aprovação conforme Norma GMW 17136) 1 validação conforme Norma GMW17136 para Termo retrátil E02000700 R$ 31.731,33 Scrap 6 horas técnicas Alteração de comprimento considerado 1 dia de lote para Scrap. | G18: Sim | H18: GEM
B19: CR-0161019-03 | C19: IVER | D19: EWO 4489010 | E19: 45217 | F19: Sem impacto para corte e Lead Prep. ( Analise feita base Delta Cut Sheet e Delta BOM ) Scrap R$ 7.608,42 Alteração de comprimento considerado 1 dia de lote para Scrap. | G19: Sim | H19: GEM
B20: CR-0161020-02 | C20: IVER | D20: EWO#4489010 | E20: 45217 | F20: Considerar sem impacto para corte Lead Prep.( Analise feita base Delta Cut Sheet e Delta BOM, implementação condicionada aos investimentos reportados na CR-0160595-02, testes e aprovação conforme Norma GMW 17136) Scrap R$ R$ 5.397,92 Alteração de comprimento considerado 1 dia de lote para Scrap. | G20: Sim | H20: GEM
B21: CR-0161022-02 | C21: APPV | D21: EWO 4489010 | E21: 45217 | F21: Considerar sem impacto para corte Lead Prep.( Analise feita base Delta Cut Sheet e Delta BOM, implementação condicionada aos investimentos reportados na CR-0160595-02, testes e aprovação conforme Norma GMW 17136) Scrap R$ 27.223,08 Alteração de comprimento considerado 1 dia de lote para Scrap. | G21: Sim | H21: GEM
B22: CR-0162211-00 | C22: APPV | D22: EWO 4489010 | E22: 45246 | F22: • 4 mini aplicadores • 8 validações conforme norma USCAR21 • 17 validações conforme norma USCAR45 • 2 validações conforme norma USCAR 38 • 31 validações conforme norma GMW17136. • 5 pacotes de polaseal. • 2 Rolos Contact • 6 Rolos dupla face • 40 horas de gráfica. • 1 rolo de vinil ( Para gráfica lear ) • 480 horas técnicas para validações • Scrap R$ R$ 22.832,72 Conforme alinhamento com Logística @Chagas, Robson Dos Santos Foi analisado e encontrado inconsistência em algumas aplicações: Segue abaixo as inconsistências encontradas, e já está sendo tratado pelo ABarbosa@lear.com | G22: Sim | H22: GEM
B23: CR-0164612-00 | C23: APPV | D23: EWO 4489010 | E23: 45247 | F23: • 09 validações conforme norma USCAR 45 • 21 VALIDAÇÕES CONFORME NORMA GMW17136. • Scrap R$21.229,85 | G23: Não | H23: GEM
B24: CR-0166437-00 | C24: MVBs | D24: 4489010 | E24: 45250 | F24: #N/A | G24: Não | H24: GEM
B25: CR-0168267-00 | C25: APPV | D25: 4590640 | E25: 45257 | F25: Descrição: 1. GEM B NARROW BODY HARNESS 52182307 MY26 MVBS Sem necessidade de investimento para engenharia corte/lead prep | G25: Não | H25: GEM
B26: CR-0166437-01 | C26: APPV | D26: 4489010 | E26: 45257 | F26: Favor considerar: • 06 calhas de selo (01 para o selo 320452329 e 5 para o selo 3204505B1) selo novo e volume alto • 06 mini aplicadores • 31 validações conforme norma USCAR21 • 14 validações conforme norma USCAR45 • 05 validações conforme norma USCAR 38 • 26 validações conforme norma GMW17136. • 4 pacotes de polaseal. • 80 horas de gráfica. • Horas técnicas para as validações 400 hs. • Scrap 21.229,85 | G26: Sim | H26: GEM
B27: CR-0168626-00 | C27: APPV | D27: 4489010 | E27: 45257 | F27: Descrição: 1. Esta CR foi criada apenas para analise dos investimentos referente a evolução da CG4210 para os itens mostrados no anexos para o MY26. Só não vamos considerar os circuitos para teste de impedancia (Item 11.5.4) . Devemos Considerar os cabos de antena e USB. As modificações tecnicas do produto serão cotadas através de outras CRs especificas. Sem necessidade de investimento para engenharia corte/lead prep | G27: Sim | H27: GEM
B28: CR-0164612-01 | C28: APPV | D28: EWO 4489010 | E28: 45259 | F28: • 09 validações conforme norma USCAR 45 • 21 VALIDAÇÕES CONFORME NORMA GMW17136. • Scrap R$21.229,85 | G28: Sim | H28: GEM
B29: CR-0168269-00 | C29: MVBs | D29: EWO 4590640 | E29: 45259 | F29: 18 validações conforme Norma USCAR 45 19 validações conforme Norma GMW 17136 3 validações conforme Norma USCAR 38 320 horas técnicas. Analise de Scrap considerando 1 dia de estoque base LCR 1280 Cars dia, @Martins, Guilherme; @Chagas, Robson Dos Santos favor validar os valores e revisar se necessário em anexo circuitos que estão saindo conforme delta cut da CCR-0168269-00 scrap 1 dia LCR 1280 TAKE RATE Scrap circuitos R$ 107.130,14 scrap 1 dia LCR 1280 TAKE RATE Scrap tubo R$ 823,97 scrap 1 dia LCR 1280 TAKE RATE Scrap Splice pronta R$ 34.044,28 scrap 1 dia LCR 1280 TAKE RATE Scrap Multicrimp pronta R$ 2.074,27 scrap 1 dia LCR 1280 TAKE RATE Scrap Termo R$ 2.832,45 Scrap Total R$ 146.905,11 | G29: Não | H29: GEM
B30: CR-0168559-00 | C30: APPV | D30: 4590640 | E30: 45259 | F30: Considerar sem impacto para corte Lead prep. Scrap R$ 113,68 circuito Wire Nb 6817 morrendo. | G30: Não | H30: GEM
B31: CR-0168949-00 | C31: APPV | D31: 4590640 | E31: 45260 | G31: Não | H31: GEM
B32: CR-0168984-00 | C32: APPV | D32: 4489010 | E32: 45261 | F32: 18 validações conforme Norma USCAR 45 | G32: Não | H32: GEM
B33: CR-0168559-01 | C33: MVBs | D33: 4590640 | E33: 45273 | F33: 2 validações conforme norma USCAR 45. 2 validações conforme norma GMW17136 32 Horas técnicas Scrap circuito R$ 113,27 Considerando 1 dia LCR Scrap Splice pronta R$ 1.282,10 Considerando 1 dia LCR Scrap Termo R$ 198,44 Considerando 1 dia LCR Scrap validação Splice R$ R$ 187,95 Conforme alinhado e reunião hoje , favor desconsiderar investimento reportado nessa CR, pois delta cut está gerando informação na Section 4:DELTA SPLICE que não será aplicada. 07-02-2024 | G33: Não | H33: GEM
B34: CR-0171841-00 | C34: APPV | E34: 45302 | F34: Considerar sem impacto para corte e Lead Prep.( Analise realizada base delta Cut Delta BOM.) | G34: Não | H34: GEM
B35: CR-0171865-00 | C35: PPV | D35: ECR4633774 | E35: 45303 | F35: Favor considerar: • Scrap : R$447,92 | G35: Não | H35: GEM
B36: CR-0172163-00 | C36: PPV | D36: TBD | E36: 45308 | F36: Não aplica para corte e Lead Prep | G36: Não | H36: GEM
B37: CR-0172366-00 | C37: PPV | D37: 4634774 | E37: 45308 | F37: Considerar em impacto para corte e Lead Prep. | G37: Não | H37: GEM
B38: CR-0172424-00 | C38: APPV | D38: 4634774 | E38: 45309 | F38: Considerar sem impacto para área de corte lead Prep. | G38: Não | H38: GEM
B39: CR-0172460-00 | C39: APPV | E39: 45310 | F39: #N/A | G39: Não | H39: GEM
B40: CR-0172477-00 | D40: 4634774 | E40: 45310 | F40: #N/A | G40: Não | H40: GEM
...

Sheet MY26 Validações Uscar e GMW
A1: Terminal | B1: Selo | C1: Extra Component PN | D1: CHP USCAR21 | E1: CSA Left | F1: CSA Right | G1: CSA Total | H1: W1 | I1: W2 | J1: W3 | K1: W4 | L1: L1 | M1: L2 | N1: L3 | O1: L4 | P1: L5 | Q1: L6 | R1: L7 | S1: R1 | T1: R2 | U1: R3 | V1: R4 | W1: R5 | X1: R6 | Y1: R7 | Z1: X1 | AA1: X2 | AB1: X3 | AC1: X4 | AD1: X5 | AE1: USCAR38 | AF1: Uscar 45 | AG1: GMW17136 | AH1: USCAR 21 | AI1: Horas tecnicas | AJ1: MY | AK1: CHP
C2: 3299362G2 | E2: 1.2 | F2: 0.5 | G2: 1.7 | L2: 0.35 | M2: 0.5 | N2: 0.35 | S2: 0.5 | AF2: X | AG2: X | AI2: 16 | AK2: =CONCATENATE(A2,"-",B2,"-",C2,"-",E2,"-",F2,"-",G2,"-",H2,"-",I2,"-",J2,"-",K2,"-",L2,"-",M2,"-",N2,"-",O2,"-",P2,"-",Q2,"-",R2,"-",S2,"-",T2,"-",U2,"-",V2,"-",W2,"-",X2,"-",Y2,"-",Z2,"-",AA2,"-",AB2,"-",AC2,"-",AD2) -> --3299362G2-1,2-0,5-1,7-----0,35-0,5-0,35-----0,5----------- | AL2: =VLOOKUP(AK2,Planilha1!B:C,2,0) -> 1 | AM2: CR-0171416-00 BODY CARBON
C3: 3299362G2 | E3: 0.7 | F3: 1 | G3: 1.7 | L3: 0.35 | M3: 0.35 | S3: 0.5 | T3: 0.5 | AG3: X | AI3: 8 | AK3: =CONCATENATE(A3,"-",B3,"-",C3,"-",E3,"-",F3,"-",G3,"-",H3,"-",I3,"-",J3,"-",K3,"-",L3,"-",M3,"-",N3,"-",O3,"-",P3,"-",Q3,"-",R3,"-",S3,"-",T3,"-",U3,"-",V3,"-",W3,"-",X3,"-",Y3,"-",Z3,"-",AA3,"-",AB3,"-",AC3,"-",AD3) -> --3299362G2-0,7-1-1,7-----0,35-0,35------0,5-0,5---------- | AL3: =VLOOKUP(AK3,Planilha1!B:C,2,0) -> 2 | AM3: CR-0171416-00 BODY CARBON
C4: E16718500 | E4: 1.05 | F4: 0.35 | G4: 1.4 | L4: 0.35 | M4: 0.35 | N4: 0.35 | S4: 0.35 | AG4: X | AI4: 8 | AK4: =CONCATENATE(A4,"-",B4,"-",C4,"-",E4,"-",F4,"-",G4,"-",H4,"-",I4,"-",J4,"-",K4,"-",L4,"-",M4,"-",N4,"-",O4,"-",P4,"-",Q4,"-",R4,"-",S4,"-",T4,"-",U4,"-",V4,"-",W4,"-",X4,"-",Y4,"-",Z4,"-",AA4,"-",AB4,"-",AC4,"-",AD4) -> --E16718500-1,05-0,35-1,4-----0,35-0,35-0,35-----0,35----------- | AL4: =VLOOKUP(AK4,Planilha1!B:C,2,0) -> 3 | AM4: CR-0171416-00 BODY CARBON
C5: E16718500 | E5: 1.05 | F5: 0.35 | G5: 1.4 | L5: 0.35 | M5: 0.35 | N5: 0.35 | S5: 0.35 | AG5: X | AI5: 8 | AJ5: 2026 | AK5: =CONCATENATE(A5,"-",B5,"-",C5,"-",E5,"-",F5,"-",G5,"-",H5,"-",I5,"-",J5,"-",K5,"-",L5,"-",M5,"-",N5,"-",O5,"-",P5,"-",Q5,"-",R5,"-",S5,"-",T5,"-",U5,"-",V5,"-",W5,"-",X5,"-",Y5,"-",Z5,"-",AA5,"-",AB5,"-",AC5,"-",AD5) -> --E16718500-1,05-0,35-1,4-----0,35-0,35-0,35-----0,35----------- | AL5: =VLOOKUP(AK5,Planilha1!B:C,2,0) -> 3 | AM5: CR-0166437-01 BODY
C6: E16718500 | E6: 0.35 | F6: 0.7 | G6: 1.05 | L6: 0.35 | S6: 0.35 | T6: 0.35 | AG6: X | AI6: 8 | AK6: =CONCATENATE(A6,"-",B6,"-",C6,"-",E6,"-",F6,"-",G6,"-",H6,"-",I6,"-",J6,"-",K6,"-",L6,"-",M6,"-",N6,"-",O6,"-",P6,"-",Q6,"-",R6,"-",S6,"-",T6,"-",U6,"-",V6,"-",W6,"-",X6,"-",Y6,"-",Z6,"-",AA6,"-",AB6,"-",AC6,"-",AD6) -> --E16718500-0,35-0,7-1,05-----0,35-------0,35-0,35---------- | AL6: =VLOOKUP(AK6,Planilha1!B:C,2,0) -> 4 | AM6: CR-0171416-00 BODY CARBON
C7: E16718500 | E7: 0.35 | F7: 0.7 | G7: 1.05 | L7: 0.35 | S7: 0.35 | T7: 0.35 | AG7: X | AI7: 8 | AK7: =CONCATENATE(A7,"-",B7,"-",C7,"-",E7,"-",F7,"-",G7,"-",H7,"-",I7,"-",J7,"-",K7,"-",L7,"-",M7,"-",N7,"-",O7,"-",P7,"-",Q7,"-",R7,"-",S7,"-",T7,"-",U7,"-",V7,"-",W7,"-",X7,"-",Y7,"-",Z7,"-",AA7,"-",AB7,"-",AC7,"-",AD7) -> --E16718500-0,35-0,7-1,05-----0,35-------0,35-0,35---------- | AL7: =VLOOKUP(AK7,Planilha1!B:C,2,0) -> 4 | AM7: CR-0171595-00 IP HARNESS carbon
C8: 3299362M9 | E8: 3.35 | F8: 4 | G8: 7.35 | L8: 0.35 | M8: 0.5 | N8: 2.5 | S8: 1 | T8: 3 | AF8: X | AG8: X | AI8: 16 | AK8: =CONCATENATE(A8,"-",B8,"-",C8,"-",E8,"-",F8,"-",G8,"-",H8,"-",I8,"-",J8,"-",K8,"-",L8,"-",M8,"-",N8,"-",O8,"-",P8,"-",Q8,"-",R8,"-",S8,"-",T8,"-",U8,"-",V8,"-",W8,"-",X8,"-",Y8,"-",Z8,"-",AA8,"-",AB8,"-",AC8,"-",AD8) -> --3299362M9-3,35-4-7,35-----0,35-0,5-2,5-----1-3---------- | AL8: =VLOOKUP(AK8,Planilha1!B:C,2,0) -> 5 | AM8: CR-0171416-00 BODY CARBON
