Workbook

Sheet Consulta
A1: ESPECIFICAÇÕES
A3: ITEM REF. | B3: G00-SP294_1_X1.00 | H3: OBRIGATÓRIO
A4: PROCESSO | B4: SOLDA LINEAR | H4: OBRIGATÓRIO
A5: NORMA | B5: GMW17136 | H5: OBRIGATÓRIO
A6: ISOLAÇÃO CABO | B6: NA
A7: TERMINAL | B7: NA
A8: SELO | B8: NA | H8: =IF(B5="GMW17136","NÃO",IF(B5="USCAR21","SOMENTE APLICAÇÕES COM SELO",IF(B5="USCAR38","NÃO",IF(B5="IEC","AVALIAR","NÃO")))) -> NÃO
A9: TERMO | B9: 3299362G2 | H9: =IF(B5="GMW17136","SIM",IF(B5="IEC","AVALIAR","NÃO")) -> SIM
A10: LADO 1
A11: BITOLA | B11: 0.35 | C11: 0.5 | D11: 0.75 | E11: 1 | F11: 1.5 | G11: 2 | H11: 2.5 | I11: 3 | J11: 4 | K11: 5 | L11: 6 | M11: 8 | N11: 10 | O11: 16 | P11: 25 | Q11: 30 | R11: 35
A12: QTD | B12: 2 | C12: 1 | D12: 0 | E12: 0 | F12: 0 | G12: 0 | H12: 0 | I12: 0 | J12: 0 | K12: 0 | L12: 0 | M12: 0 | N12: 0 | O12: 0 | P12: 0 | Q12: 0 | R12: 0
A13: SOMA DE BITOLAS LADO 1 | B13: =SUMPRODUCT(B11:R11,B12:R12) -> 1.2
A14: LADO 2
A15: BITOLA | B15: 0.35 | C15: 0.5 | D15: 0.75 | E15: 1 | F15: 1.5 | G15: 2 | H15: 2.5 | I15: 3 | J15: 4 | K15: 5 | L15: 6 | M15: 8 | N15: 10 | O15: 16 | P15: 25 | Q15: 30 | R15: 35
A16: QTD | B16: 0 | C16: 1 | D16: 0 | E16: 0 | F16: 0 | G16: 0 | H16: 0 | I16: 0 | J16: 0 | K16: 0 | L16: 0 | M16: 0 | N16: 0 | O16: 0 | P16: 0 | Q16: 0 | R16: 0
A17: SOMA DE BITOLAS LADO 2 | B17: =SUMPRODUCT(B15:R15,B16:R16) -> 0.5
A18: SOMA DE BITOLA TOTAL | B18: =B13+B17 -> 1.7
A20: RESULTADO
A22: VALIDAÇÃO INTERNA | B22: =IF(OR(ISERROR(_xlfn.XLOOKUP(_xlfn.CONCAT(B9&B18,IF(B13>B17,_xlfn.TEXTJOIN(,TRUE,B12:R12,B16:R16),_xlfn.TEXTJOIN(,TRUE,B16:R16,B12:R12))),Controle!BO:BO,Controle!BB:BB))=FALSE,ISERROR(_xlfn.XLOOKUP(_xlfn.CONCAT(B9&B18,IF(B13>B17,_xlfn.TEXTJOIN(,TRUE,B12:R12,B16:R16),_xlfn.TEXTJOIN(,TRUE,B16:R16,B12:R12))),Controle!BO:BO,Controle!AW:AW))),"LOCALIZADO","NÃO LOCALIZADO") -> LOCALIZADO
A23: CR | B23: =IF(B22="NÃO LOCALIZADO","",_xlfn.XLOOKUP(_xlfn.CONCAT(B9&B18,IF(B13>B17,_xlfn.TEXTJOIN(,TRUE,B12:R12,B16:R16),_xlfn.TEXTJOIN(,TRUE,B16:R16,B12:R12))),Controle!BO:BO,Controle!AW:AW)) -> #N/A
A24: CÓDIGO RELATÓRIO | B24: =IF(B22="NÃO LOCALIZADO","",IF(_xlfn.XLOOKUP(_xlfn.CONCAT(B9&B18,IF(B13>B17,_xlfn.TEXTJOIN(,TRUE,B12:R12,B16:R16),_xlfn.TEXTJOIN(,TRUE,B16:R16,B12:R12))),Controle!BO:BO,Controle!BB:BB)<>"",_xlfn.XLOOKUP(_xlfn.CONCAT(B9&B18,IF(B13>B17,_xlfn.TEXTJOIN(,TRUE,B12:R12,B16:R16),_xlfn.TEXTJOIN(,TRUE,B16:R16,B12:R12))),Controle!BO:BO,Controle!BB:BB),"")) -> #N/A
A25: DATA | B25: =IF(B22="NÃO LOCALIZADO","",IF(_xlfn.XLOOKUP(_xlfn.CONCAT(B9&B18,IF(B13>B17,_xlfn.TEXTJOIN(,TRUE,B12:R12,B16:R16),_xlfn.TEXTJOIN(,TRUE,B16:R16,B12:R12))),Controle!BO:BO,Controle!BC:BC)="","",_xlfn.XLOOKUP(_xlfn.CONCAT(B9&B18,IF(B13>B17,_xlfn.TEXTJOIN(,TRUE,B12:R12,B16:R16),_xlfn.TEXTJOIN(,TRUE,B16:R16,B12:R12))),Controle!BO:BO,Controle!BC:BC))) -> #N/A
A26: EMISSOR | B26: =IF(B22="NÃO LOCALIZADO","",IF(_xlfn.XLOOKUP(_xlfn.CONCAT(B9&B18,IF(B13>B17,_xlfn.TEXTJOIN(,TRUE,B12:R12,B16:R16),_xlfn.TEXTJOIN(,TRUE,B16:R16,B12:R12))),Controle!BO:BO,Controle!BD:BD)="","",_xlfn.XLOOKUP(_xlfn.CONCAT(B9&B18,IF(B13>B17,_xlfn.TEXTJOIN(,TRUE,B12:R12,B16:R16),_xlfn.TEXTJOIN(,TRUE,B16:R16,B12:R12))),Controle!BO:BO,Controle!BD:BD))) -> #N/A
A27: QTD AMOSTRAS | B27: =IF(B22="NÃO LOCALIZADO","",IF(_xlfn.XLOOKUP(_xlfn.CONCAT(B9&B18,IF(B13>B17,_xlfn.TEXTJOIN(,TRUE,B12:R12,B16:R16),_xlfn.TEXTJOIN(,TRUE,B16:R16,B12:R12))),Controle!BO:BO,Controle!BA:BA)="","",_xlfn.XLOOKUP(_xlfn.CONCAT(B9&B18,IF(B13>B17,_xlfn.TEXTJOIN(,TRUE,B12:R12,B16:R16),_xlfn.TEXTJOIN(,TRUE,B16:R16,B12:R12))),Controle!BO:BO,Controle!BA:BA))) -> #N/A
A28: APROVADOR | B28: =IF(B22="NÃO LOCALIZADO","",IF(_xlfn.XLOOKUP(_xlfn.CONCAT(B9&B18,IF(B13>B17,_xlfn.TEXTJOIN(,TRUE,B12:R12,B16:R16),_xlfn.TEXTJOIN(,TRUE,B16:R16,B12:R12))),Controle!BO:BO,Controle!BF:BF)="","",_xlfn.XLOOKUP(_xlfn.CONCAT(B9&B18,IF(B13>B17,_xlfn.TEXTJOIN(,TRUE,B12:R12,B16:R16),_xlfn.TEXTJOIN(,TRUE,B16:R16,B12:R12))),Controle!BO:BO,Controle!BF:BF))) -> #N/A
A30: VALIDAÇÃO EXTERNA | B30: =IF(ISERROR(_xlfn.XLOOKUP(_xlfn.CONCAT(B9&B18,IF(B13>B17,_xlfn.TEXTJOIN(,TRUE,B12:R12,B16:R16),_xlfn.TEXTJOIN(,TRUE,B16:R16,B12:R12))),Controle!BO:BO,Controle!BM:BM))=FALSE,"LOCALIZADO","NÃO LOCALIZADO") -> NÃO LOCALIZADO
A31: CÓDIGO FORNECEDOR | B31: =IF(B30="NÃO LOCALIZADO","",IF(_xlfn.XLOOKUP(_xlfn.CONCAT(B9&B18,IF(B13>B17,_xlfn.TEXTJOIN(,TRUE,B12:R12,B16:R16),_xlfn.TEXTJOIN(,TRUE,B16:R16,B12:R12))),Controle!BO:BO,Controle!BM:BM)=0,"",_xlfn.XLOOKUP(_xlfn.CONCAT(B9&B18,IF(B13>B17,_xlfn.TEXTJOIN(,TRUE,B12:R12,B16:R16),_xlfn.TEXTJOIN(,TRUE,B16:R16,B12:R12))),Controle!BO:BO,Controle!BM:BM)))
A32: DATA | B32: =IF(B30="NÃO LOCALIZADO","",IF(_xlfn.XLOOKUP(_xlfn.CONCAT(B9&B18,IF(B13>B17,_xlfn.TEXTJOIN(,TRUE,B12:R12,B16:R16),_xlfn.TEXTJOIN(,TRUE,B16:R16,B12:R12))),Controle!BO:BO,Controle!#REF!)=0,"",_xlfn.XLOOKUP(_xlfn.CONCAT(B9&B18,IF(B13>B17,_xlfn.TEXTJOIN(,TRUE,B12:R12,B16:R16),_xlfn.TEXTJOIN(,TRUE,B16:R16,B12:R12))),Controle!BO:BO,Controle!#REF!)))
A33: FORNECEDOR | B33: =IF(B30="NÃO LOCALIZADO","",IF(_xlfn.XLOOKUP(_xlfn.CONCAT(B9&B18,IF(B13>B17,_xlfn.TEXTJOIN(,TRUE,B12:R12,B16:R16),_xlfn.TEXTJOIN(,TRUE,B16:R16,B12:R12))),Controle!BO:BO,Controle!BN:BN)=0,"",_xlfn.XLOOKUP(_xlfn.CONCAT(B9&B18,IF(B13>B17,_xlfn.TEXTJOIN(,TRUE,B12:R12,B16:R16),_xlfn.TEXTJOIN(,TRUE,B16:R16,B12:R12))),Controle!BO:BO,Controle!BN:BN)))
A34: QTD AMOSTRAS | B34: =IF(B30="NÃO LOCALIZADO","",IF(_xlfn.XLOOKUP(_xlfn.CONCAT(B9&B18,IF(B13>B17,_xlfn.TEXTJOIN(,TRUE,B12:R12,B16:R16),_xlfn.TEXTJOIN(,TRUE,B16:R16,B12:R12))),Controle!BO:BO,Controle!#REF!)=0,"",_xlfn.XLOOKUP(_xlfn.CONCAT(B9&B18,IF(B13>B17,_xlfn.TEXTJOIN(,TRUE,B12:R12,B16:R16),_xlfn.TEXTJOIN(,TRUE,B16:R16,B12:R12))),Controle!BO:BO,Controle!#REF!)))
A35: APROVADOR | B35: =IF(B30="NÃO LOCALIZADO","",IF(_xlfn.XLOOKUP(_xlfn.CONCAT(B9&B18,IF(B13>B17,_xlfn.TEXTJOIN(,TRUE,B12:R12,B16:R16),_xlfn.TEXTJOIN(,TRUE,B16:R16,B12:R12))),Controle!BO:BO,Controle!#REF!)=0,"",_xlfn.XLOOKUP(_xlfn.CONCAT(B9&B18,IF(B13>B17,_xlfn.TEXTJOIN(,TRUE,B12:R12,B16:R16),_xlfn.TEXTJOIN(,TRUE,B16:R16,B12:R12))),Controle!BO:BO,Controle!#REF!)))
A36: DATA | B36: =IF(B30="NÃO LOCALIZADO","",IF(_xlfn.XLOOKUP(_xlfn.CONCAT(B9&B18,IF(B13>B17,_xlfn.TEXTJOIN(,TRUE,B12:R12,B16:R16),_xlfn.TEXTJOIN(,TRUE,B16:R16,B12:R12))),Controle!BO:BO,Controle!#REF!)=0,"",_xlfn.XLOOKUP(_xlfn.CONCAT(B9&B18,IF(B13>B17,_xlfn.TEXTJOIN(,TRUE,B12:R12,B16:R16),_xlfn.TEXTJOIN(,TRUE,B16:R16,B12:R12))),Controle!BO:BO,Controle!#REF!)))

Sheet Relatório
A1: ESPECIFICAÇÕES
D2: ISOLAÇÃO | H2: SOMA DE BITOLAS | L2: LADO 1 | AC2: LADO 2 | AX2: VALIDAÇÃO DE PROCESSO (PV) | BB2: VALIDAÇÃO DE PRODUTO (DV)
A3: ITEM REF. | B3: PROCESSO | C3: NORMA | D3: CABO | E3: TERMINAL | F3: SELO | G3: TERMO | H3: LADO 1 | I3: LADO 2 | J3: TOTAL | K3: CONFIGURAÇÃO | L3: 0.35 | M3: 0.5 | N3: 0.75 | O3: 1 | P3: 1.5 | Q3: 2 | R3: 2.5 | S3: 3 | T3: 4 | U3: 5 | V3: 6 | W3: 8 | X3: 10 | Y3: 16 | Z3: 25 | AA3: 30 | AB3: 35 | AC3: 0.35 | AD3: 0.5 | AE3: 0.75 | AF3: 1 | AG3: 1.5 | AH3: 2 | AI3: 2.5 | AJ3: 3 | AK3: 4 | AL3: 5 | AM3: 6 | AN3: 8 | AO3: 10 | AP3: 16 | AQ3: 25 | AR3: 30 | AS3: 35 | AT3: STATUS VALIDAÇÃO | AU3: CR | AV3: CÓDIGO RELATÓRIO | AW3: NOME DO ARQUIVO | AX3: DATA | AY3: EMISSOR | AZ3: QTD AMOSTRAS | BA3: APROVADO | BB3: CÓDIGO FORNECEDOR | BC3: DATA | BD3: FORNECEDOR | BE3: QTD AMOSTRAS | BF3: APROVADO | BG3: DATA
A4: G00-SP294_1_X1.00 | B4: SOLDA LINEAR | C4: GMW17136 | D4: NA | G4: E16718500 | H4: =SUMPRODUCT(L3:AB3,L4:AB4) -> 2.5 | I4: =SUMPRODUCT(AC3:AS3,AC4:AS4) -> 0.1225 | J4: =H4+I4 -> 2.6225 | K4: 0,75+0,75+1,00X0,75+0,75 | L4: 0 | M4: 0 | N4: 2 | O4: 1 | P4: 0 | Q4: 0 | R4: 0 | S4: 0 | T4: 0 | U4: 0 | V4: 0 | W4: 0 | X4: 0 | Y4: 0 | Z4: 0 | AA4: 0 | AB4: 0 | AC4: 0.35 | AD4: 0 | AE4: 0 | AF4: 0 | AG4: 0 | AH4: 0 | AI4: 0 | AJ4: 0 | AK4: 0 | AL4: 0 | AM4: 0 | AN4: 0 | AO4: 0 | AP4: 0 | AQ4: 0 | AR4: 0 | AS4: 0 | AT4: =IF(ISERROR(_xlfn.XLOOKUP(_xlfn.CONCAT(G4&J4,IF(H4>I4,_xlfn.TEXTJOIN(,TRUE,L4:AB4,AC4:AS4),_xlfn.TEXTJOIN(,TRUE,AC4:AS4,L4:AB4))),Controle!BO:BO,Controle!BB:BB))=FALSE,"LOCALIZADO","NÃO LOCALIZADO") -> NÃO LOCALIZADO | AU4: =IF(AT4="NÃO LOCALIZADO","",_xlfn.XLOOKUP(_xlfn.CONCAT(G4&J4,IF(H4>I4,_xlfn.TEXTJOIN(,TRUE,L4:AB4,AC4:AS4),_xlfn.TEXTJOIN(,TRUE,AC4:AS4,L4:AB4))),Controle!BO:BO,Controle!AW:AW)) | AW4: =CONCATENATE("L1 (",H4,") + L2 (",I4,") ",G4," - 0101 - ",C4) -> L1 (2,5) + L2 (0,1225) E16718500 - 0101 - GMW17136 | AX4: 45395 | AY4: XXXXXXXXXXXXXXX | AZ4: 999 | BA4: SIM | BB4: 2311008-0/007 | BC4: 45394 | BD4: XXXXXXXXXXXXXXX | BE4: 99 | BF4: SIM | BG4: 45395
H5: =SUMPRODUCT(L4:AB4,L5:AB5) -> 0 | I5: =SUMPRODUCT(AC4:AS4,AC5:AS5) -> 0.175 | J5: =H5+I5 -> 0.175 | L5: 0 | M5: 0 | N5: 0 | O5: 0 | P5: 0 | Q5: 0 | R5: 0 | S5: 0 | T5: 0 | U5: 0 | V5: 0 | W5: 0 | X5: 0 | Y5: 0 | Z5: 0 | AA5: 0 | AB5: 0 | AC5: 0.5 | AD5: 0 | AE5: 0 | AF5: 0 | AG5: 0 | AH5: 0 | AI5: 0 | AJ5: 0 | AK5: 0 | AL5: 0 | AM5: 0 | AN5: 0 | AO5: 0 | AP5: 0 | AQ5: 0 | AR5: 0 | AS5: 0
A6: SP1792_1_X1 | B6: SOLDA LINEAR | C6: GMW17136 | G6: E16718500 | H6: =SUMPRODUCT(L5:AB5,L6:AB6) -> 0 | I6: =SUMPRODUCT(AC5:AS5,AC6:AS6) -> 0.175 | J6: =H6+I6 -> 0.175 | L6: 0.35 | M6: 0 | N6: 0 | O6: 0 | P6: 0 | Q6: 0 | R6: 0 | S6: 0 | T6: 0 | U6: 0 | V6: 0 | W6: 0 | X6: 0 | Y6: 0 | Z6: 0 | AA6: 0 | AB6: 0 | AC6: 0.35 | AD6: 0 | AE6: 0 | AF6: 0 | AG6: 0 | AH6: 0 | AI6: 0 | AJ6: 0 | AK6: 0 | AL6: 0 | AM6: 0 | AN6: 0 | AO6: 0 | AP6: 0 | AQ6: 0 | AR6: 0 | AS6: 0
A7: SP117_3_X1.00 | B7: SOLDA LINEAR | C7: GMW17136 | G7: E16718500 | H7: =SUMPRODUCT(L6:AB6,L7:AB7) -> 0.175 | I7: =SUMPRODUCT(AC6:AS6,AC7:AS7) -> 0.175 | J7: =H7+I7 -> 0.35 | L7: 0.5 | M7: 0.5 | N7: 0 | O7: 0 | P7: 0 | Q7: 0 | R7: 0 | S7: 0 | T7: 0 | U7: 0 | V7: 0 | W7: 0 | X7: 0 | Y7: 0 | Z7: 0 | AA7: 0 | AB7: 0 | AC7: 0.5 | AD7: 0 | AE7: 0 | AF7: 0 | AG7: 0 | AH7: 0 | AI7: 0 | AJ7: 0 | AK7: 0 | AL7: 0 | AM7: 0 | AN7: 0 | AO7: 0 | AP7: 0 | AQ7: 0 | AR7: 0 | AS7: 0
A8: SP2250_1_X1.01 | B8: SOLDA LINEAR | C8: GMW17136 | G8: E16725300 | H8: =SUMPRODUCT(L7:AB7,L8:AB8) -> 0.625 | I8: =SUMPRODUCT(AC7:AS7,AC8:AS8) -> 0.25 | J8: =H8+I8 -> 0.875 | L8: 0.75 | M8: 0.5 | N8: 0 | O8: 0 | P8: 0 | Q8: 0 | R8: 0 | S8: 0 | T8: 0 | U8: 0 | V8: 0 | W8: 0 | X8: 0 | Y8: 0 | Z8: 0 | AA8: 0 | AB8: 0 | AC8: 0.5 | AD8: 0.5 | AE8: 0 | AF8: 0 | AG8: 0 | AH8: 0 | AI8: 0 | AJ8: 0 | AK8: 0 | AL8: 0 | AM8: 0 | AN8: 0 | AO8: 0 | AP8: 0 | AQ8: 0 | AR8: 0 | AS8: 0
A9: SP117_3_X1 | B9: SOLDA LINEAR | C9: GMW17136 | G9: E16718500 | H9: =SUMPRODUCT(L8:AB8,L9:AB9) -> 0.8125 | I9: =SUMPRODUCT(AC8:AS8,AC9:AS9) -> 0.625 | J9: =H9+I9 -> 1.4375 | L9: 0.75 | M9: 0.5 | N9: 0 | O9: 0 | P9: 0 | Q9: 0 | R9: 0 | S9: 0 | T9: 0 | U9: 0 | V9: 0 | W9: 0 | X9: 0 | Y9: 0 | Z9: 0 | AA9: 0 | AB9: 0 | AC9: 0.5 | AD9: 0.75 | AE9: 0.5 | AF9: 0 | AG9: 0 | AH9: 0 | AI9: 0 | AJ9: 0 | AK9: 0 | AL9: 0 | AM9: 0 | AN9: 0 | AO9: 0 | AP9: 0 | AQ9: 0 | AR9: 0 | AS9: 0
A10: SP118_3_X1.00 | B10: SOLDA LINEAR | C10: GMW17136 | G10: E16718500 | H10: =SUMPRODUCT(L9:AB9,L10:AB10) -> 0.5625 | I10: =SUMPRODUCT(AC9:AS9,AC10:AS10) -> 0 | J10: =H10+I10 -> 0.5625 | L10: 0.75 | M10: 0 | N10: 0 | O10: 0 | P10: 0 | Q10: 0 | R10: 0 | S10: 0 | T10: 0 | U10: 0 | V10: 0 | W10: 0 | X10: 0 | Y10: 0 | Z10: 0 | AA10: 0 | AB10: 0 | AC10: 0 | AD10: 0 | AE10: 0 | AF10: 0 | AG10: 0 | AH10: 0 | AI10: 0 | AJ10: 0 | AK10: 0 | AL10: 0 | AM10: 0 | AN10: 0 | AO10: 0 | AP10: 0 | AQ10: 0 | AR10: 0 | AS10: 0
A11: SP201_3_X1.00 | B11: SOLDA TOPO | C11: GMW17136 | G11: E16718500 | H11: =SUMPRODUCT(L10:AB10,L11:AB11) -> 0 | I11: =SUMPRODUCT(AC10:AS10,AC11:AS11) -> 0 | J11: =H11+I11 -> 0 | L11: 0 | M11: 0 | N11: 0 | O11: 0 | P11: 0 | Q11: 0 | R11: 0 | S11: 0 | T11: 0 | U11: 0 | V11: 0 | W11: 0 | X11: 0 | Y11: 0 | Z11: 0 | AA11: 0 | AB11: 0 | AC11: 0.35 | AD11: 0.35 | AE11: 0 | AF11: 0 | AG11: 0 | AH11: 0 | AI11: 0 | AJ11: 0 | AK11: 0 | AL11: 0 | AM11: 0 | AN11: 0 | AO11: 0 | AP11: 0 | AQ11: 0 | AR11: 0 | AS11: 0
A12: SP2250_2_X1 | B12: SOLDA TOPO | C12: GMW17136 | G12: E16718500 | H12: =SUMPRODUCT(L11:AB11,L12:AB12) -> 0 | I12: =SUMPRODUCT(AC11:AS11,AC12:AS12) -> 0.2975 | J12: =H12+I12 -> 0.2975 | L12: 0.75 | M12: 0.75 | N12: 0.35 | O12: 0 | P12: 0 | Q12: 0 | R12: 0 | S12: 0 | T12: 0 | U12: 0 | V12: 0 | W12: 0 | X12: 0 | Y12: 0 | Z12: 0 | AA12: 0 | AB12: 0 | AC12: 0.35 | AD12: 0.5 | AE12: 0 | AF12: 0 | AG12: 0 | AH12: 0 | AI12: 0 | AJ12: 0 | AK12: 0 | AL12: 0 | AM12: 0 | AN12: 0 | AO12: 0 | AP12: 0 | AQ12: 0 | AR12: 0 | AS12: 0
A13: SP2250_1_X1 | B13: SOLDA LINEAR | C13: GMW17136 | G13: E16725300 | H13: =SUMPRODUCT(L12:AB12,L13:AB13) -> 0.9375 | I13: =SUMPRODUCT(AC12:AS12,AC13:AS13) -> 0.2975 | J13: =H13+I13 -> 1.235 | L13: 0.75 | M13: 0.5 | N13: 0 | O13: 0 | P13: 0 | Q13: 0 | R13: 0 | S13: 0 | T13: 0 | U13: 0 | V13: 0 | W13: 0 | X13: 0 | Y13: 0 | Z13: 0 | AA13: 0 | AB13: 0 | AC13: 0.35 | AD13: 0.35 | AE13: 0.35 | AF13: 0 | AG13: 0 | AH13: 0 | AI13: 0 | AJ13: 0 | AK13: 0 | AL13: 0 | AM13: 0 | AN13: 0 | AO13: 0 | AP13: 0 | AQ13: 0 | AR13: 0 | AS13: 0
A14: SP2250_1_X1.06 | B14: SOLDA LINEAR | C14: GMW17136 | G14: E16725300 | H14: =SUMPRODUCT(L13:AB13,L14:AB14) -> 0.6375 | I14: =SUMPRODUCT(AC13:AS13,AC14:AS14) -> 0.6125 | J14: =H14+I14 -> 1.25 | L14: 0.35 | M14: 0.75 | N14: 0 | O14: 0 | P14: 0 | Q14: 0 | R14: 0 | S14: 0 | T14: 0 | U14: 0 | V14: 0 | W14: 0 | X14: 0 | Y14: 0 | Z14: 0 | AA14: 0 | AB14: 0 | AC14: 0.5 | AD14: 0.5 | AE14: 0.75 | AF14: 0 | AG14: 0 | AH14: 0 | AI14: 0 | AJ14: 0 | AK14: 0 | AL14: 0 | AM14: 0 | AN14: 0 | AO14: 0 | AP14: 0 | AQ14: 0 | AR14: 0 | AS14: 0
A15: SP6817_1_X1.01 | B15: SOLDA LINEAR | C15: GMW17136 | G15: E16718500 | H15: =SUMPRODUCT(L14:AB14,L15:AB15) -> 0.385 | I15: =SUMPRODUCT(AC14:AS14,AC15:AS15) -> 0.375 | J15: =H15+I15 -> 0.76 | L15: 0.35 | M15: 0.35 | N15: 0.35 | O15: 0 | P15: 0 | Q15: 0 | R15: 0 | S15: 0 | T15: 0 | U15: 0 | V15: 0 | W15: 0 | X15: 0 | Y15: 0 | Z15: 0 | AA15: 0 | AB15: 0 | AC15: 0.75 | AD15: 0 | AE15: 0 | AF15: 0 | AG15: 0 | AH15: 0 | AI15: 0 | AJ15: 0 | AK15: 0 | AL15: 0 | AM15: 0 | AN15: 0 | AO15: 0 | AP15: 0 | AQ15: 0 | AR15: 0 | AS15: 0
A16: SP1740_1_X1 | B16: SOLDA LINEAR | C16: GMW17136 | G16: E16718500 | H16: =SUMPRODUCT(L15:AB15,L16:AB16) -> 0.175 | I16: =SUMPRODUCT(AC15:AS15,AC16:AS16) -> 0.2625 | J16: =H16+I16 -> 0.4375 | L16: 0.5 | M16: 0 | N16: 0 | O16: 0 | P16: 0 | Q16: 0 | R16: 0 | S16: 0 | T16: 0 | U16: 0 | V16: 0 | W16: 0 | X16: 0 | Y16: 0 | Z16: 0 | AA16: 0 | AB16: 0 | AC16: 0.35 | AD16: 0.35 | AE16: 0.5 | AF16: 0 | AG16: 0 | AH16: 0 | AI16: 0 | AJ16: 0 | AK16: 0 | AL16: 0 | AM16: 0 | AN16: 0 | AO16: 0 | AP16: 0 | AQ16: 0 | AR16: 0 | AS16: 0
A17: SP1740_1_X1.00 | B17: SOLDA LINEAR | C17: GMW17136 | G17: E16718500 | H17: =SUMPRODUCT(L16:AB16,L17:AB17) -> 0.25 | I17: =SUMPRODUCT(AC16:AS16,AC17:AS17) -> 0.42 | J17: =H17+I17 -> 0.67 | L17: 0.5 | M17: 0.5 | N17: 0.5 | O17: 0 | P17: 0 | Q17: 0 | R17: 0 | S17: 0 | T17: 0 | U17: 0 | V17: 0 | W17: 0 | X17: 0 | Y17: 0 | Z17: 0 | AA17: 0 | AB17: 0 | AC17: 0.35 | AD17: 0.35 | AE17: 0.35 | AF17: 0 | AG17: 0 | AH17: 0 | AI17: 0 | AJ17: 0 | AK17: 0 | AL17: 0 | AM17: 0 | AN17: 0 | AO17: 0 | AP17: 0 | AQ17: 0 | AR17: 0 | AS17: 0
... A25: SP2350_1_X1.00 | B25: SOLDA LINEAR | C25: GMW17136 | G25: E16725300 | H25: =SUMPRODUCT(L24:AB24,L25:AB25) -> 0 | I25: =SUMPRODUCT(AC24:AS24,AC25:AS25) -> 0 | J25: =H25+I25 -> 0 | L25: 2.5 | M25: 0.5 | N25: 0 | O25: 0 | P25: 0 | Q25: 0 | R25: 0 | S25: 0 | T25: 0 | U25: 0 | V25: 0 | W25: 0 | X25: 0 | Y25: 0 | Z25: 0 | AA25: 0 | AB25: 0 | AC25: 0 | AD25: 0 | AE25: 0 | AF25: 0 | AG25: 0 | AH25: 0 | AI25: 0 | AJ25: 0 | AK25: 0 | AL25: 0 | AM25: 0 | AN25: 0 | AO25: 0 | AP25: 0 | AQ25: 0 | AR25: 0 | AS25: 0
H26: =SUMPRODUCT(L25:AB25,L26:AB26) -> 0 | I26: =SUMPRODUCT(AC25:AS25,AC26:AS26) -> 0 | J26: =H26+I26 -> 0 | L26: 0 | M26: 0 | N26: 0 | O26: 0 | P26: 0 | Q26: 0 | R26: 0 | S26: 0 | T26: 0 | U26: 0 | V26: 0 | W26: 0 | X26: 0 | Y26: 0 | Z26: 0 | AA26: 0 | AB26: 0 | AC26: 0 | AD26: 0 | AE26: 0 | AF26: 0 | AG26: 0 | AH26: 0 | AI26: 0 | AJ26: 0 | AK26: 0 | AL26: 0 | AM26: 0 | AN26: 0 | AO26: 0 | AP26: 0 | AQ26: 0 | AR26: 0 | AS26: 0
H27: =SUMPRODUCT(L26:AB26,L27:AB27) -> 0 | I27: =SUMPRODUCT(AC26:AS26,AC27:AS27) -> 0 | J27: =H27+I27 -> 0 | L27: 0 | M27: 0 | N27: 0 | O27: 0 | P27: 0 | Q27: 0 | R27: 0 | S27: 0 | T27: 0 | U27: 0 | V27: 0 | W27: 0 | X27: 0 | Y27: 0 | Z27: 0 | AA27: 0 | AB27: 0 | AC27: 0 | AD27: 0 | AE27: 0 | AF27: 0 | AG27: 0 | AH27: 0 | AI27: 0 | AJ27: 0 | AK27: 0 | AL27: 0 | AM27: 0 | AN27: 0 | AO27: 0 | AP27: 0 | AQ27: 0 | AR27: 0 | AS27: 0
H28: =SUMPRODUCT(L27:AB27,L28:AB28) -> 0 | I28: =SUMPRODUCT(AC27:AS27,AC28:AS28) -> 0 | J28: =H28+I28 -> 0 | L28: 0 | M28: 0 | N28: 0 | O28: 0 | P28: 0 | Q28: 0 | R28: 0 | S28: 0 | T28: 0 | U28: 0 | V28: 0 | W28: 0 | X28: 0 | Y28: 0 | Z28: 0 | AA28: 0 | AB28: 0 | AC28: 0 | AD28: 0 | AE28: 0 | AF28: 0 | AG28: 0 | AH28: 0 | AI28: 0 | AJ28: 0 | AK28: 0 | AL28: 0 | AM28: 0 | AN28: 0 | AO28: 0 | AP28: 0 | AQ28: 0 | AR28: 0 | AS28: 0
H29: =SUMPRODUCT(L28:AB28,L29:AB29) -> 0 | I29: =SUMPRODUCT(AC28:AS28,AC29:AS29) -> 0 | J29: =H29+I29 -> 0 | L29: 0 | M29: 0 | N29: 0 | O29: 0 | P29: 0 | Q29: 0 | R29: 0 | S29: 0 | T29: 0 | U29: 0 | V29: 0 | W29: 0 | X29: 0 | Y29: 0 | Z29: 0 | AA29: 0 | AB29: 0 | AC29: 0 | AD29: 0 | AE29: 0 | AF29: 0 | AG29: 0 | AH29: 0 | AI29: 0 | AJ29: 0 | AK29: 0 | AL29: 0 | AM29: 0 | AN29: 0 | AO29: 0 | AP29: 0 | AQ29: 0 | AR29: 0 | AS29: 0
H30: =SUMPRODUCT(L29:AB29,L30:AB30) -> 0 | I30: =SUMPRODUCT(AC29:AS29,AC30:AS30) -> 0 | J30: =H30+I30 -> 0 | L30: 0 | M30: 0 | N30: 0 | O30: 0 | P30: 0 | Q30: 0 | R30: 0 | S30: 0 | T30: 0 | U30: 0 | V30: 0 | W30: 0 | X30: 0 | Y30: 0 | Z30: 0 | AA30: 0 | AB30: 0 | AC30: 0 | AD30: 0 | AE30: 0 | AF30: 0 | AG30: 0 | AH30: 0 | AI30: 0 | AJ30: 0 | AK30: 0 | AL30: 0 | AM30: 0 | AN30: 0 | AO30: 0 | AP30: 0 | AQ30: 0 | AR30: 0 | AS30: 0
H31: =SUMPRODUCT(L30:AB30,L31:AB31) -> 0 | I31: =SUMPRODUCT(AC30:AS30,AC31:AS31) -> 0 | J31: =H31+I31 -> 0 | L31: 0 | M31: 0 | N31: 0 | O31: 0 | P31: 0 | Q31: 0 | R31: 0 | S31: 0 | T31: 0 | U31: 0 | V31: 0 | W31: 0 | X31: 0 | Y31: 0 | Z31: 0 | AA31: 0 | AB31: 0 | AC31: 0 | AD31: 0 | AE31: 0 | AF31: 0 | AG31: 0 | AH31: 0 | AI31: 0 | AJ31: 0 | AK31: 0 | AL31: 0 | AM31: 0 | AN31: 0 | AO31: 0 | AP31: 0 | AQ31: 0 | AR31: 0 | AS31: 0
H32: =SUMPRODUCT(L31:AB31,L32:AB32) -> 0 | I32: =SUMPRODUCT(AC31:AS31,AC32:AS32) -> 0 | J32: =H32+I32 -> 0 | L32: 0 | M32: 0 | N32: 0 | O32: 0 | P32: 0 | Q32: 0 | R32: 0 | S32: 0 | T32: 0 | U32: 0 | V32: 0 | W32: 0 | X32: 0 | Y32: 0 | Z32: 0 | AA32: 0 | AB32: 0 | AC32: 0 | AD32: 0 | AE32: 0 | AF32: 0 | AG32: 0 | AH32: 0 | AI32: 0 | AJ32: 0 | AK32: 0 | AL32: 0 | AM32: 0 | AN32: 0 | AO32: 0 | AP32: 0 | AQ32: 0 | AR32: 0 | AS32: 0
H33: =SUMPRODUCT(L32:AB32,L33:AB33) -> 0 | I33: =SUMPRODUCT(AC32:AS32,AC33:AS33) -> 0 | J33: =H33+I33 -> 0 | L33: 0 | M33: 0 | N33: 0 | O33: 0 | P33: 0 | Q33: 0 | R33: 0 | S33: 0 | T33: 0 | U33: 0 | V33: 0 | W33: 0 | X33: 0 | Y33: 0 | Z33: 0 | AA33: 0 | AB33: 0 | AC33: 0 | AD33: 0 | AE33: 0 | AF33: 0 | AG33: 0 | AH33: 0 | AI33: 0 | AJ33: 0 | AK33: 0 | AL33: 0 | AM33: 0 | AN33: 0 | AO33: 0 | AP33: 0 | AQ33: 0 | AR33: 0 | AS33: 0
H34: =SUMPRODUCT(L33:AB33,L34:AB34) -> 0 | I34: =SUMPRODUCT(AC33:AS33,AC34:AS34) -> 0 | J34: =H34+I34 -> 0 | L34: 0 | M34: 0 | N34: 0 | O34: 0 | P34: 0 | Q34: 0 | R34: 0 | S34: 0 | T34: 0 | U34: 0 | V34: 0 | W34: 0 | X34: 0 | Y34: 0 | Z34: 0 | AA34: 0 | AB34: 0 | AC34: 0 | AD34: 0 | AE34: 0 | AF34: 0 | AG34: 0 | AH34: 0 | AI34: 0 | AJ34: 0 | AK34: 0 | AL34: 0 | AM34: 0 | AN34: 0 | AO34: 0 | AP34: 0 | AQ34: 0 | AR34: 0 | AS34: 0
H35: =SUMPRODUCT(L34:AB34,L35:AB35) -> 0 | I35: =SUMPRODUCT(AC34:AS34,AC35:AS35) -> 0 | J35: =H35+I35 -> 0 | L35: 0 | M35: 0 | N35: 0 | O35: 0 | P35: 0 | Q35: 0 | R35: 0 | S35: 0 | T35: 0 | U35: 0 | V35: 0 | W35: 0 | X35: 0 | Y35: 0 | Z35: 0 | AA35: 0 | AB35: 0 | AC35: 0 | AD35: 0 | AE35: 0 | AF35: 0 | AG35: 0 | AH35: 0 | AI35: 0 | AJ35: 0 | AK35: 0 | AL35: 0 | AM35: 0 | AN35: 0 | AO35: 0 | AP35: 0 | AQ35: 0 | AR35: 0 | AS35: 0
H36: =SUMPRODUCT(L35:AB35,L36:AB36) -> 0 | I36: =SUMPRODUCT(AC35:AS35,AC36:AS36) -> 0 | J36: =H36+I36 -> 0 | L36: 0 | M36: 0 | N36: 0 | O36: 0 | P36: 0 | Q36: 0 | R36: 0 | S36: 0 | T36: 0 | U36: 0 | V36: 0 | W36: 0 | X36: 0 | Y36: 0 | Z36: 0 | AA36: 0 | AB36: 0 | AC36: 0 | AD36: 0 | AE36: 0 | AF36: 0 | AG36: 0 | AH36: 0 | AI36: 0 | AJ36: 0 | AK36: 0 | AL36: 0 | AM36: 0 | AN36: 0 | AO36: 0 | AP36: 0 | AQ36: 0 | AR36: 0 | AS36: 0
H37: =SUMPRODUCT(L36:AB36,L37:AB37) -> 0 | I37: =SUMPRODUCT(AC36:AS36,AC37:AS37) -> 0 | J37: =H37+I37 -> 0 | L37: 0 | M37: 0 | N37: 0 | O37: 0 | P37: 0 | Q37: 0 | R37: 0 | S37: 0 | T37: 0 | U37: 0 | V37: 0 | W37: 0 | X37: 0 | Y37: 0 | Z37: 0 | AA37: 0 | AB37: 0 | AC37: 0 | AD37: 0 | AE37: 0 | AF37: 0 | AG37: 0 | AH37: 0 | AI37: 0 | AJ37: 0 | AK37: 0 | AL37: 0 | AM37: 0 | AN37: 0 | AO37: 0 | AP37: 0 | AQ37: 0 | AR37: 0 | AS37: 0
... H50: =SUMPRODUCT(L49:AB49,L50:AB50) -> 0 | I50: =SUMPRODUCT(AC49:AS49,AC50:AS50) -> 0 | J50: =H50+I50 -> 0 | L50: 0 | M50: 0 | N50: 0 | O50: 0 | P50: 0 | Q50: 0 | R50: 0 | S50: 0 | T50: 0 | U50: 0 | V50: 0 | W50: 0 | X50: 0 | Y50: 0 | Z50: 0 | AA50: 0 | AB50: 0 | AC50: 0 | AD50: 0 | AE50: 0 | AF50: 0 | AG50: 0 | AH50: 0 | AI50: 0 | AJ50: 0 | AK50: 0 | AL50: 0 | AM50: 0 | AN50: 0 | AO50: 0 | AP50: 0 | AQ50: 0 | AR50: 0 | AS50: 0
D55: NA

Sheet Status Validação
A1: STATUS
A2: SOLICITADO CR
A3: VALIDAÇÃO CONCLUIDA
A4: VALIDAÇÃO EM ANDAMENTO
A5: SEM VALIDAÇÃO

Sheet Controle
C1: FAMILIA | E1: CONFIGURAÇÃO | O1: CONFIGURAÇÃO LADO 1 | AF1: CONFIGURAÇÃO LADO 2 | AW1: COTAÇÃO | BA1: RELATÓRIO | BM1: RELATÓRIO DE VALIDAÇÃO EXTERNA | BO1: CHAVE PRIMÁRIA
A2: PROJETO | B2: NORMA | C2: CÓDIGO | D2: DESCRIÇÃO | E2: PROCESSO | F2: ITEM REF. | G2: CÓDIGO-ITEM REF. | H2: ISOLAÇÃO CABO | I2: TERMINAL | J2: SELO | K2: TERMO | L2: LADO 1 | M2: LADO 2 | N2: TOTAL | O2: 0.35 | P2: 0.5 | Q2: 0.75 | R2: 1 | S2: 1.5 | T2: 2 | U2: 2.5 | V2: 3 | W2: 4 | X2: 5 | Y2: 6 | Z2: 8 | AA2: 10 | AB2: 16 | AC2: 25 | AD2: 30 | AE2: 35 | AF2: 0.35 | AG2: 0.5 | AH2: 0.75 | AI2: 1 | AJ2: 1.5 | AK2: 2 | AL2: 2.5 | AM2: 3 | AN2: 4 | AO2: 5 | AP2: 6 | AQ2: 8 | AR2: 10 | AS2: 16 | AT2: 25 | AU2: 30 | AV2: 35 | AW2: CR | AX2: PROJETO | AY2: TIPO VERBA | AZ2: VALOR UNIT. | BA2: AMOSTRAS | BB2: CÓDIGO | BC2: DATA | BD2: EMISSOR | BE2: REVISADOR | BF2: APROVADOR | BG2: DT / VT | BH2: RC | BI2: PO | BJ2: SENF | BK2: ORDEM DE REMESSA | BL2: NF | BM2: CODIGO | BN2: FORNECEDOR | BO2: CHAVE GMW | BP2: CHAVE USCAR45 | BQ2: BUSQUEDA GMW
A3: GEM | B3: GMW17136 | D3: =IF(_xlfn.XLOOKUP(C3,'Tabela de Familias'!A:A,'Tabela de Familias'!B:B)="","") | F3: SP294_1_X1.00 | G3: =IF(F3="","",C3&"-"&F3) -> -SP294_1_X1.00 | K3: E16718500 | L3: {=SUMPRODUCT(O3:AE3*$O$2:$AE$2)} -> 2.5 | M3: {=SUMPRODUCT(AF3:AV3*$AF$2:$AV$2)} -> 1.5 | N3: =L3+M3 -> 4 | O3: 0 | P3: 0 | Q3: 2 | R3: 1 | S3: 0 | T3: 0 | U3: 0 | V3: 0 | W3: 0 | X3: 0 | Y3: 0 | Z3: 0 | AA3: 0 | AB3: 0 | AC3: 0 | AD3: 0 | AE3: 0 | AF3: 0 | AG3: 0 | AH3: 2 | AI3: 0 | AJ3: 0 | AK3: 0 | AL3: 0 | AM3: 0 | AN3: 0 | AO3: 0 | AP3: 0 | AQ3: 0 | AR3: 0 | AS3: 0 | AT3: 0 | AU3: 0 | AV3: 0 | AW3: NA | AY3: NA | AZ3: NA | BA3: 5 | BB3: 184 | BE3: NA | BG3: NA | BH3: NA | BI3: NA | BJ3: NA | BK3: NA | BL3: NA | BM3: XXXXXXXX | BN3: ITEN | BO3: =IF(F3="","",_xlfn.CONCAT(K3&N3,IF(L3>M3,_xlfn.TEXTJOIN(,TRUE,O3:AV3),_xlfn.TEXTJOIN(,TRUE,AF3:AV3,O3:AE3)))) -> E1671850040021000000000000000200000000000000 | BP3: =_xlfn.CONCAT(B3,N3,IF(L3>M3,_xlfn.TEXTJOIN(,TRUE,O3:AV3),_xlfn.TEXTJOIN(,TRUE,AF3:AV3,O3:AE3))) -> GMW1713640021000000000000000200000000000000 | BQ3: =_xlfn.XLOOKUP(BO3,[1]Planilha1!$BU:$BU,[1]Planilha1!$BU:$BU,"",0,1)
A4: GEM | B4: GMW17136 | D4: =IF(_xlfn.XLOOKUP(C4,'Tabela de Familias'!A:A,'Tabela de Familias'!B:B)="","") | F4: SP3350_1_X1 | G4: =IF(F4="","",C4&"-"&F4) -> -SP3350_1_X1 | K4: 3299362G2 | L4: {=SUMPRODUCT(O4:AE4*$O$2:$AE$2)} -> 3.5 | M4: {=SUMPRODUCT(AF4:AV4*$AF$2:$AV$2)} -> 3 | N4: =L4+M4 -> 6.5 | O4: 0 | P4: 0 | Q4: 0 | R4: 1 | S4: 0 | T4: 0 | U4: 1 | V4: 0 | W4: 0 | X4: 0 | Y4: 0 | Z4: 0 | AA4: 0 | AB4: 0 | AC4: 0 | AD4: 0 | AE4: 0 | AF4: 0 | AG4: 1 | AH4: 0 | AI4: 0 | AJ4: 0 | AK4: 0 | AL4: 1 | AM4: 0 | AN4: 0 | AO4: 0 | AP4: 0 | AQ4: 0 | AR4: 0 | AS4: 0 | AT4: 0 | AU4: 0 | AV4: 0 | AW4: NA | AY4: NA | AZ4: NA | BA4: 125 | BB4: 186 | BE4: NA | BG4: NA | BH4: NA | BI4: NA | BJ4: NA | BK4: NA | BL4: NA | BO4: =IF(F4="","",_xlfn.CONCAT(K4&N4,IF(L4>M4,_xlfn.TEXTJOIN(,TRUE,O4:AV4),_xlfn.TEXTJOIN(,TRUE,AF4:AV4,O4:AE4)))) -> 3299362G26,50001001000000000001000010000000000 | BP4: =_xlfn.CONCAT(B4,N4,IF(L4>M4,_xlfn.TEXTJOIN(,TRUE,O4:AV4),_xlfn.TEXTJOIN(,TRUE,AF4:AV4,O4:AE4))) -> GMW171366,50001001000000000001000010000000000 | BQ4: =_xlfn.XLOOKUP(BO4,[1]Planilha1!$BU:$BU,[1]Planilha1!$BU:$BU,"",0,1)
A5: GEM | B5: GMW17136 | D5: =IF(_xlfn.XLOOKUP(C5,'Tabela de Familias'!A:A,'Tabela de Familias'!B:B)="","") | F5: MULTI-47_X633G101_ | G5: =IF(F5="","",C5&"-"&F5) -> -MULTI-47_X633G101_ | K5: 3299365JY | L5: {=SUMPRODUCT(O5:AE5*$O$2:$AE$2)} -> 3 | M5: {=SUMPRODUCT(AF5:AV5*$AF$2:$AV$2)} -> 0 | N5: =L5+M5 -> 3 | O5: 0 | P5: 2 | Q5: 0 | R5: 0 | S5: 0 | T5: 1 | U5: 0 | V5: 0 | W5: 0 | X5: 0 | Y5: 0 | Z5: 0 | AA5: 0 | AB5: 0 | AC5: 0 | AD5: 0 | AE5: 0 | AF5: 0 | AG5: 0 | AH5: 0 | AI5: 0 | AJ5: 0 | AK5: 0 | AL5: 0 | AM5: 0 | AN5: 0 | AO5: 0 | AP5: 0 | AQ5: 0 | AR5: 0 | AS5: 0 | AT5: 0 | AU5: 0 | AV5: 0 | AW5: NA | AY5: NA | AZ5: NA | BA5: 3 | BB5: 0001BBT | BE5: NA | BG5: NA | BH5: NA | BI5: NA | BJ5: NA | BK5: NA | BL5: NA | BO5: =IF(F5="","",_xlfn.CONCAT(K5&N5,IF(L5>M5,_xlfn.TEXTJOIN(,TRUE,O5:AV5),_xlfn.TEXTJOIN(,TRUE,AF5:AV5,O5:AE5)))) -> 3299365JY30200010000000000000000000000000000 | BP5: =_xlfn.CONCAT(B5,N5,IF(L5>M5,_xlfn.TEXTJOIN(,TRUE,O5:AV5),_xlfn.TEXTJOIN(,TRUE,AF5:AV5,O5:AE5))) -> GMW1713630200010000000000000000000000000000 | BQ5: =_xlfn.XLOOKUP(BO5,[1]Planilha1!$BU:$BU,[1]Planilha1!$BU:$BU,"",0,1)
A6: GEM | B6: GMW17136 | D6: =IF(_xlfn.XLOOKUP(C6,'Tabela de Familias'!A:A,'Tabela de Familias'!B:B)="","") | F6: SP1301.00 | G6: =IF(F6="","",C6&"-"&F6) -> -SP1301.00 | K6: E14168900 | L6: {=SUMPRODUCT(O6:AE6*$O$2:$AE$2)} -> 0 | M6: {=SUMPRODUCT(AF6:AV6*$AF$2:$AV$2)} -> 3 | N6: =L6+M6 -> 3 | O6: 0 | P6: 0 | Q6: 0 | R6: 0 | S6: 0 | T6: 0 | U6: 0 | V6: 0 | W6: 0 | X6: 0 | Y6: 0 | Z6: 0 | AA6: 0 | AB6: 0 | AC6: 0 | AD6: 0 | AE6: 0 | AF6: 0 | AG6: 0 | AH6: 0 | AI6: 3 | AJ6: 0 | AK6: 0 | AL6: 0 | AM6: 0 | AN6: 0 | AO6: 0 | AP6: 0 | AQ6: 0 | AR6: 0 | AS6: 0 | AT6: 0 | AU6: 0 | AV6: 0 | AW6: NA | AY6: NA | AZ6: NA | BA6: 3 | BB6: 00100BBT | BE6: NA | BG6: NA | BH6: NA | BI6: NA | BJ6: NA | BK6: NA | BL6: NA | BO6: =IF(F6="","",_xlfn.CONCAT(K6&N6,IF(L6>M6,_xlfn.TEXTJOIN(,TRUE,O6:AV6),_xlfn.TEXTJOIN(,TRUE,AF6:AV6,O6:AE6)))) -> E1416890030003000000000000000000000000000000 | BP6: =_xlfn.CONCAT(B6,N6,IF(L6>M6,_xlfn.TEXTJOIN(,TRUE,O6:AV6),_xlfn.TEXTJOIN(,TRUE,AF6:AV6,O6:AE6))) -> GMW1713630003000000000000000000000000000000 | BQ6: =_xlfn.XLOOKUP(BO6,[1]Planilha1!$BU:$BU,[1]Planilha1!$BU:$BU,"",0,1)
A7: GEM | B7: GMW17136 | D7: =IF(_xlfn.XLOOKUP(C7,'Tabela de Familias'!A:A,'Tabela de Familias'!B:B)="","") | F7: SP1798.00 | G7: =IF(F7="","",C7&"-"&F7) -> -SP1798.00 | K7: E14168800 | L7: {=SUMPRODUCT(O7:AE7*$O$2:$AE$2)} -> 1.05 | M7: {=SUMPRODUCT(AF7:AV7*$AF$2:$AV$2)} -> 0.35 | N7: =L7+M7 -> 1.4 | O7: 3 | P7: 0 | Q7: 0 | R7: 0 | S7: 0 | T7: 0 | U7: 0 | V7: 0 | W7: 0 | X7: 0 | Y7: 0 | Z7: 0 | AA7: 0 | AB7: 0 | AC7: 0 | AD7: 0 | AE7: 0 | AF7: 1 | AG7: 0 | AH7: 0 | AI7: 0 | AJ7: 0 | AK7: 0 | AL7: 0 | AM7: 0 | AN7: 0 | AO7: 0 | AP7: 0 | AQ7: 0 | AR7: 0 | AS7: 0 | AT7: 0 | AU7: 0 | AV7: 0 | AW7: NA | AY7: NA | AZ7: NA | BA7: 3 | BB7: 00101BBT | BE7: NA | BG7: NA | BH7: NA | BI7: NA | BJ7: NA | BK7: NA | BL7: NA | BO7: =IF(F7="","",_xlfn.CONCAT(K7&N7,IF(L7>M7,_xlfn.TEXTJOIN(,TRUE,O7:AV7),_xlfn.TEXTJOIN(,TRUE,AF7:AV7,O7:AE7)))) -> E141688001,43000000000000000010000000000000000 | BP7: =_xlfn.CONCAT(B7,N7,IF(L7>M7,_xlfn.TEXTJOIN(,TRUE,O7:AV7),_xlfn.TEXTJOIN(,TRUE,AF7:AV7,O7:AE7))) -> GMW171361,43000000000000000010000000000000000 | BQ7: =_xlfn.XLOOKUP(BO7,[1]Planilha1!$BU:$BU,[1]Planilha1!$BU:$BU,"",0,1)
A8: GEM | B8: GMW17136 | D8: =IF(_xlfn.XLOOKUP(C8,'Tabela de Familias'!A:A,'Tabela de Familias'!B:B)="","") | F8: SP1940 | G8: =IF(F8="","",C8&"-"&F8) -> -SP1940 | K8: E14168900 | L8: {=SUMPRODUCT(O8:AE8*$O$2:$AE$2)} -> 1.05 | M8: {=SUMPRODUCT(AF8:AV8*$AF$2:$AV$2)} -> 0.35 | N8: =L8+M8 -> 1.4 | O8: 3 | P8: 0 | Q8: 0 | R8: 0 | S8: 0 | T8: 0 | U8: 0 | V8: 0 | W8: 0 | X8: 0 | Y8: 0 | Z8: 0 | AA8: 0 | AB8: 0 | AC8: 0 | AD8: 0 | AE8: 0 | AF8: 1 | AG8: 0 | AH8: 0 | AI8: 0 | AJ8: 0 | AK8: 0 | AL8: 0 | AM8: 0 | AN8: 0 | AO8: 0 | AP8: 0 | AQ8: 0 | AR8: 0 | AS8: 0 | AT8: 0 | AU8: 0 | AV8: 0 | AW8: NA | AY8: NA | AZ8: NA | BA8: 3 | BB8: 00102BBT | BE8: NA | BG8: NA | BH8: NA | BI8: NA | BJ8: NA | BK8: NA | BL8: NA | BO8: =IF(F8="","",_xlfn.CONCAT(K8&N8,IF(L8>M8,_xlfn.TEXTJOIN(,TRUE,O8:AV8),_xlfn.TEXTJOIN(,TRUE,AF8:AV8,O8:AE8)))) -> E141689001,43000000000000000010000000000000000 | BP8: =_xlfn.CONCAT(B8,N8,IF(L8>M8,_xlfn.TEXTJOIN(,TRUE,O8:AV8),_xlfn.TEXTJOIN(,TRUE,AF8:AV8,O8:AE8))) -> GMW171361,43000000000000000010000000000000000 | BQ8: =_xlfn.XLOOKUP(BO8,[1]Planilha1!$BU:$BU,[1]Planilha1!$BU:$BU,"",0,1)
A9: GEM | B9: GMW17136 | D9: =IF(_xlfn.XLOOKUP(C9,'Tabela de Familias'!A:A,'Tabela de Familias'!B:B)="","") | F9: SP200 | G9: =IF(F9="","",C9&"-"&F9) -> -SP200 | K9: E14168800 | L9: {=SUMPRODUCT(O9:AE9*$O$2:$AE$2)} -> 1 | M9: {=SUMPRODUCT(AF9:AV9*$AF$2:$AV$2)} -> 0.5 | N9: =L9+M9 -> 1.5 | O9: 0 | P9: 2 | Q9: 0 | R9: 0 | S9: 0 | T9: 0 | U9: 0 | V9: 0 | W9: 0 | X9: 0 | Y9: 0 | Z9: 0 | AA9: 0 | AB9: 0 | AC9: 0 | AD9: 0 | AE9: 0 | AF9: 0 | AG9: 1 | AH9: 0 | AI9: 0 | AJ9: 0 | AK9: 0 | AL9: 0 | AM9: 0 | AN9: 0 | AO9: 0 | AP9: 0 | AQ9: 0 | AR9: 0 | AS9: 0 | AT9: 0 | AU9: 0 | AV9: 0 | AW9: NA | AY9: NA | AZ9: NA | BA9: 3 | BB9: 00103BBT | BE9: NA | BG9: NA | BH9: NA | BI9: NA | BJ9: NA | BK9: NA | BL9: NA | BO9: =IF(F9="","",_xlfn.CONCAT(K9&N9,IF(L9>M9,_xlfn.TEXTJOIN(,TRUE,O9:AV9),_xlfn.TEXTJOIN(,TRUE,AF9:AV9,O9:AE9)))) -> E141688001,50200000000000000001000000000000000 | BP9: =_xlfn.CONCAT(B9,N9,IF(L9>M9,_xlfn.TEXTJOIN(,TRUE,O9:AV9),_xlfn.TEXTJOIN(,TRUE,AF9:AV9,O9:AE9))) -> GMW171361,50200000000000000001000000000000000 | BQ9: =_xlfn.XLOOKUP(BO9,[1]Planilha1!$BU:$BU,[1]Planilha1!$BU:$BU,"",0,1)
A10: GEM | B10: GMW17136 | D10: =IF(_xlfn.XLOOKUP(C10,'Tabela de Familias'!A:A,'Tabela de Familias'!B:B)="","") | F10: SP200.00 | G10: =IF(F10="","",C10&"-"&F10) -> -SP200.00 | K10: E14168800 | L10: {=SUMPRODUCT(O10:AE10*$O$2:$AE$2)} -> 1.5 | M10: {=SUMPRODUCT(AF10:AV10*$AF$2:$AV$2)} -> 0 | N10: =L10+M10 -> 1.5 | O10: 0 | P10: 3 | Q10: 0 | R10: 0 | S10: 0 | T10: 0 | U10: 0 | V10: 0 | W10: 0 | X10: 0 | Y10: 0 | Z10: 0 | AA10: 0 | AB10: 0 | AC10: 0 | AD10: 0 | AE10: 0 | AF10: 0 | AG10: 0 | AH10: 0 | AI10: 0 | AJ10: 0 | AK10: 0 | AL10: 0 | AM10: 0 | AN10: 0 | AO10: 0 | AP10: 0 | AQ10: 0 | AR10: 0 | AS10: 0 | AT10: 0 | AU10: 0 | AV10: 0 | AW10: NA | AY10: NA | AZ10: NA | BA10: 3 | BB10: 00104BBT | BE10: NA | BG10: NA | BH10: NA | BI10: NA | BJ10: NA | BK10: NA | BL10: NA | BO10: =IF(F10="","",_xlfn.CONCAT(K10&N10,IF(L10>M10,_xlfn.TEXTJOIN(,TRUE,O10:AV10),_xlfn.TEXTJOIN(,TRUE,AF10:AV10,O10:AE10)))) -> E141688001,50300000000000000000000000000000000 | BP10: =_xlfn.CONCAT(B10,N10,IF(L10>M10,_xlfn.TEXTJOIN(,TRUE,O10:AV10),_xlfn.TEXTJOIN(,TRUE,AF10:AV10,O10:AE10))) -> GMW171361,50300000000000000000000000000000000 | BQ10: =_xlfn.XLOOKUP(BO10,[1]Planilha1!$BU:$BU,[1]Planilha1!$BU:$BU,"",0,1)
A11: GEM | B11: GMW17136 | D11: =IF(_xlfn.XLOOKUP(C11,'Tabela de Familias'!A:A,'Tabela de Familias'!B:B)="","") | F11: SP201 | G11: =IF(F11="","",C11&"-"&F11) -> -SP201 | K11: E14168800 | L11: {=SUMPRODUCT(O11:AE11*$O$2:$AE$2)} -> 1 | M11: {=SUMPRODUCT(AF11:AV11*$AF$2:$AV$2)} -> 0.5 | N11: =L11+M11 -> 1.5 | O11: 0 | P11: 2 | Q11: 0 | R11: 0 | S11: 0 | T11: 0 | U11: 0 | V11: 0 | W11: 0 | X11: 0 | Y11: 0 | Z11: 0 | AA11: 0 | AB11: 0 | AC11: 0 | AD11: 0 | AE11: 0 | AF11: 0 | AG11: 1 | AH11: 0 | AI11: 0 | AJ11: 0 | AK11: 0 | AL11: 0 | AM11: 0 | AN11: 0 | AO11: 0 | AP11: 0 | AQ11: 0 | AR11: 0 | AS11: 0 | AT11: 0 | AU11: 0 | AV11: 0 | AW11: NA | AY11: NA | AZ11: NA | BA11: 3 | BB11: 00105BBT | BE11: NA | BG11: NA | BH11: NA | BI11: NA | BJ11: NA | BK11: NA | BL11: NA | BO11: =IF(F11="","",_xlfn.CONCAT(K11&N11,IF(L11>M11,_xlfn.TEXTJOIN(,TRUE,O11:AV11),_xlfn.TEXTJOIN(,TRUE,AF11:AV11,O11:AE11)))) -> E141688001,50200000000000000001000000000000000 | BP11: =_xlfn.CONCAT(B11,N11,IF(L11>M11,_xlfn.TEXTJOIN(,TRUE,O11:AV11),_xlfn.TEXTJOIN(,TRUE,AF11:AV11,O11:AE11))) -> GMW171361,50200000000000000001000000000000000 | BQ11: =_xlfn.XLOOKUP(BO11,[1]Planilha1!$BU:$BU,[1]Planilha1!$BU:$BU,"",0,1)
A12: GEM | B12: GMW17136 | D12: =IF(_xlfn.XLOOKUP(C12,'Tabela de Familias'!A:A,'Tabela de Familias'!B:B)="","") | F12: SP201.00 | G12: =IF(F12="","",C12&"-"&F12) -> -SP201.00 | K12: E14168800 | L12: {=SUMPRODUCT(O12:AE12*$O$2:$AE$2)} -> 1 | M12: {=SUMPRODUCT(AF12:AV12*$AF$2:$AV$2)} -> 0.5 | N12: =L12+M12 -> 1.5 | O12: 0 | P12: 2 | Q12: 0 | R12: 0 | S12: 0 | T12: 0 | U12: 0 | V12: 0 | W12: 0 | X12: 0 | Y12: 0 | Z12: 0 | AA12: 0 | AB12: 0 | AC12: 0 | AD12: 0 | AE12: 0 | AF12: 0 | AG12: 1 | AH12: 0 | AI12: 0 | AJ12: 0 | AK12: 0 | AL12: 0 | AM12: 0 | AN12: 0 | AO12: 0 | AP12: 0 | AQ12: 0 | AR12: 0 | AS12: 0 | AT12: 0 | AU12: 0 | AV12: 0 | AW12: NA | AY12: NA | AZ12: NA | BA12: 3 | BB12: 00106BBT | BE12: NA | BG12: NA | BH12: NA | BI12: NA | BJ12: NA | BK12: NA | BL12: NA | BO12: =IF(F12="","",_xlfn.CONCAT(K12&N12,IF(L12>M12,_xlfn.TEXTJOIN(,TRUE,O12:AV12),_xlfn.TEXTJOIN(,TRUE,AF12:AV12,O12:AE12)))) -> E141688001,50200000000000000001000000000000000 | BP12: =_xlfn.CONCAT(B12,N12,IF(L12>M12,_xlfn.TEXTJOIN(,TRUE,O12:AV12),_xlfn.TEXTJOIN(,TRUE,AF12:AV12,O12:AE12))) -> GMW171361,50200000000000000001000000000000000 | BQ12: =_xlfn.XLOOKUP(BO12,[1]Planilha1!$BU:$BU,[1]Planilha1!$BU:$BU,"",0,1)
A13: GEM | B13: GMW17136 | D13: =IF(_xlfn.XLOOKUP(C13,'Tabela de Familias'!A:A,'Tabela de Familias'!B:B)="","") | F13: SP2150.00 | G13: =IF(F13="","",C13&"-"&F13) -> -SP2150.00 | K13: E14168900 | L13: {=SUMPRODUCT(O13:AE13*$O$2:$AE$2)} -> 0.35 | M13: {=SUMPRODUCT(AF13:AV13*$AF$2:$AV$2)} -> 2.9 | N13: =L13+M13 -> 3.25 | O13: 1 | P13: 0 | Q13: 0 | R13: 0 | S13: 0 | T13: 0 | U13: 0 | V13: 0 | W13: 0 | X13: 0 | Y13: 0 | Z13: 0 | AA13: 0 | AB13: 0 | AC13: 0 | AD13: 0 | AE13: 0 | AF13: 4 | AG13: 1 | AH13: 0 | AI13: 1 | AJ13: 0 | AK13: 0 | AL13: 0 | AM13: 0 | AN13: 0 | AO13: 0 | AP13: 0 | AQ13: 0 | AR13: 0 | AS13: 0 | AT13: 0 | AU13: 0 | AV13: 0 | AW13: NA | AY13: NA | AZ13: NA | BA13: 3 | BB13: 00107BBT | BE13: NA | BG13: NA | BH13: NA | BI13: NA | BJ13: NA | BK13: NA | BL13: NA | BO13: =IF(F13="","",_xlfn.CONCAT(K13&N13,IF(L13>M13,_xlfn.TEXTJOIN(,TRUE,O13:AV13),_xlfn.TEXTJOIN(,TRUE,AF13:AV13,O13:AE13)))) -> E141689003,254101000000000000010000000000000000 | BP13: =_xlfn.CONCAT(B13,N13,IF(L13>M13,_xlfn.TEXTJOIN(,TRUE,O13:AV13),_xlfn.TEXTJOIN(,TRUE,AF13:AV13,O13:AE13))) -> GMW171363,254101000000000000010000000000000000 | BQ13: =_xlfn.XLOOKUP(BO13,[1]Planilha1!$BU:$BU,[1]Planilha1!$BU:$BU,"",0,1)
A14: GEM | B14: GMW17136 | D14: =IF(_xlfn.XLOOKUP(C14,'Tabela de Familias'!A:A,'Tabela de Familias'!B:B)="","") | F14: SP2250.04 | G14: =IF(F14="","",C14&"-"&F14) -> -SP2250.04 | K14: E14168800 | L14: {=SUMPRODUCT(O14:AE14*$O$2:$AE$2)} -> 1.95 | M14: {=SUMPRODUCT(AF14:AV14*$AF$2:$AV$2)} -> 0.35 | N14: =L14+M14 -> 2.3 | O14: 2 | P14: 1 | Q14: 1 | R14: 0 | S14: 0 | T14: 0 | U14: 0 | V14: 0 | W14: 0 | X14: 0 | Y14: 0 | Z14: 0 | AA14: 0 | AB14: 0 | AC14: 0 | AD14: 0 | AE14: 0 | AF14: 1 | AG14: 0 | AH14: 0 | AI14: 0 | AJ14: 0 | AK14: 0 | AL14: 0 | AM14: 0 | AN14: 0 | AO14: 0 | AP14: 0 | AQ14: 0 | AR14: 0 | AS14: 0 | AT14: 0 | AU14: 0 | AV14: 0 | AW14: NA | AY14: NA | AZ14: NA | BA14: 3 | BB14: 00108BBT | BE14: NA | BG14: NA | BH14: NA | BI14: NA | BJ14: NA | BK14: NA | BL14: NA | BO14: =IF(F14="","",_xlfn.CONCAT(K14&N14,IF(L14>M14,_xlfn.TEXTJOIN(,TRUE,O14:AV14),_xlfn.TEXTJOIN(,TRUE,AF14:AV14,O14:AE14)))) -> E141688002,32110000000000000010000000000000000 | BP14: =_xlfn.CONCAT(B14,N14,IF(L14>M14,_xlfn.TEXTJOIN(,TRUE,O14:AV14),_xlfn.TEXTJOIN(,TRUE,AF14:AV14,O14:AE14))) -> GMW171362,32110000000000000010000000000000000 | BQ14: =_xlfn.XLOOKUP(BO14,[1]Planilha1!$BU:$BU,[1]Planilha1!$BU:$BU,"",0,1)
A15: GEM | B15: GMW17136 | D15: =IF(_xlfn.XLOOKUP(C15,'Tabela de Familias'!A:A,'Tabela de Familias'!B:B)="","") | F15: SP5214 | G15: =IF(F15="","",C15&"-"&F15) -> -SP5214 | K15: E02000700 | L15: {=SUMPRODUCT(O15:AE15*$O$2:$AE$2)} -> 1.05 | M15: {=SUMPRODUCT(AF15:AV15*$AF$2:$AV$2)} -> 1.4 | N15: =L15+M15 -> 2.45 | O15: 3 | P15: 0 | Q15: 0 | R15: 0 | S15: 0 | T15: 0 | U15: 0 | V15: 0 | W15: 0 | X15: 0 | Y15: 0 | Z15: 0 | AA15: 0 | AB15: 0 | AC15: 0 | AD15: 0 | AE15: 0 | AF15: 4 | AG15: 0 | AH15: 0 | AI15: 0 | AJ15: 0 | AK15: 0 | AL15: 0 | AM15: 0 | AN15: 0 | AO15: 0 | AP15: 0 | AQ15: 0 | AR15: 0 | AS15: 0 | AT15: 0 | AU15: 0 | AV15: 0 | AW15: NA | AY15: NA | AZ15: NA | BA15: 3 | BB15: 0010BBT | BE15: NA | BG15: NA | BH15: NA | BI15: NA | BJ15: NA | BK15: NA | BL15: NA | BO15: =IF(F15="","",_xlfn.CONCAT(K15&N15,IF(L15>M15,_xlfn.TEXTJOIN(,TRUE,O15:AV15),_xlfn.TEXTJOIN(,TRUE,AF15:AV15,O15:AE15)))) -> E020007002,454000000000000000030000000000000000 | BP15: =_xlfn.CONCAT(B15,N15,IF(L15>M15,_xlfn.TEXTJOIN(,TRUE,O15:AV15),_xlfn.TEXTJOIN(,TRUE,AF15:AV15,O15:AE15))) -> GMW171362,454000000000000000030000000000000000 | BQ15: =_xlfn.XLOOKUP(BO15,[1]Planilha1!$BU:$BU,[1]Planilha1!$BU:$BU,"",0,1)
A16: GEM | B16: GMW17136 | D16: =IF(_xlfn.XLOOKUP(C16,'Tabela de Familias'!A:A,'Tabela de Familias'!B:B)="","") | F16: SP2250.08 | G16: =IF(F16="","",C16&"-"&F16) -> -SP2250.08 | K16: E02000700 | L16: {=SUMPRODUCT(O16:AE16*$O$2:$AE$2)} -> 1.5 | M16: {=SUMPRODUCT(AF16:AV16*$AF$2:$AV$2)} -> 0 | N16: =L16+M16 -> 1.5 | O16: 0 | P16: 3 | Q16: 0 | R16: 0 | S16: 0 | T16: 0 | U16: 0 | V16: 0 | W16: 0 | X16: 0 | Y16: 0 | Z16: 0 | AA16: 0 | AB16: 0 | AC16: 0 | AD16: 0 | AE16: 0 | AF16: 0 | AG16: 0 | AH16: 0 | AI16: 0 | AJ16: 0 | AK16: 0 | AL16: 0 | AM16: 0 | AN16: 0 | AO16: 0 | AP16: 0 | AQ16: 0 | AR16: 0 | AS16: 0 | AT16: 0 | AU16: 0 | AV16: 0 | AW16: NA | AY16: NA | AZ16: NA | BA16: 3 | BB16: 00110BBT | BE16: NA | BG16: NA | BH16: NA | BI16: NA | BJ16: NA | BK16: NA | BL16: NA | BO16: =IF(F16="","",_xlfn.CONCAT(K16&N16,IF(L16>M16,_xlfn.TEXTJOIN(,TRUE,O16:AV16),_xlfn.TEXTJOIN(,TRUE,AF16:AV16,O16:AE16)))) -> E020007001,50300000000000000000000000000000000 | BP16: =_xlfn.CONCAT(B16,N16,IF(L16>M16,_xlfn.TEXTJOIN(,TRUE,O16:AV16),_xlfn.TEXTJOIN(,TRUE,AF16:AV16,O16:AE16))) -> GMW171361,50300000000000000000000000000000000 | BQ16: =_xlfn.XLOOKUP(BO16,[1]Planilha1!$BU:$BU,[1]Planilha1!$BU:$BU,"",0,1)
... A78: GEM | B78: GMW17136 | D78: =IF(_xlfn.XLOOKUP(C78,'Tabela de Familias'!A:A,'Tabela de Familias'!B:B)="","") | F78: SP6281.05 | G78: =IF(F78="","",C78&"-"&F78) -> -SP6281.05 | K78: E14168800 | L78: {=SUMPRODUCT(O78:AE78*$O$2:$AE$2)} -> 1.2 | M78: {=SUMPRODUCT(AF78:AV78*$AF$2:$AV$2)} -> 0.7 | N78: =L78+M78 -> 1.9 | O78: 2 | P78: 1 | Q78: 0 | R78: 0 | S78: 0 | T78: 0 | U78: 0 | V78: 0 | W78: 0 | X78: 0 | Y78: 0 | Z78: 0 | AA78: 0 | AB78: 0 | AC78: 0 | AD78: 0 | AE78: 0 | AF78: 2 | AG78: 0 | AH78: 0 | AI78: 0 | AJ78: 0 | AK78: 0 | AL78: 0 | AM78: 0 | AN78: 0 | AO78: 0 | AP78: 0 | AQ78: 0 | AR78: 0 | AS78: 0 | AT78: 0 | AU78: 0 | AV78: 0 | AW78: NA | AY78: NA | AZ78: NA | BA78: 3 | BB78: 00168BBT | BE78: NA | BG78: NA | BH78: NA | BI78: NA | BJ78: NA | BK78: NA | BL78: NA | BO78: =IF(F78="","",_xlfn.CONCAT(K78&N78,IF(L78>M78,_xlfn.TEXTJOIN(,TRUE,O78:AV78),_xlfn.TEXTJOIN(,TRUE,AF78:AV78,O78:AE78)))) -> E141688001,92100000000000000020000000000000000 | BP78: =_xlfn.CONCAT(B78,N78,IF(L78>M78,_xlfn.TEXTJOIN(,TRUE,O78:AV78),_xlfn.TEXTJOIN(,TRUE,AF78:AV78,O78:AE78))) -> GMW171361,92100000000000000020000000000000000 | BQ78: =_xlfn.XLOOKUP(BO78,[1]Planilha1!$BU:$BU,[1]Planilha1!$BU:$BU,"",0,1)
A79: GEM | B79: GMW17136 | D79: =IF(_xlfn.XLOOKUP(C79,'Tabela de Familias'!A:A,'Tabela de Familias'!B:B)="","") | F79: SP6817 | G79: =IF(F79="","",C79&"-"&F79) -> -SP6817 | I79: E14168600 | L79: {=SUMPRODUCT(O79:AE79*$O$2:$AE$2)} -> 0.7 | M79: {=SUMPRODUCT(AF79:AV79*$AF$2:$AV$2)} -> 0 | N79: =L79+M79 -> 0.7 | O79: 2 | P79: 0 | Q79: 0 | R79: 0 | S79: 0 | T79: 0 | U79: 0 | V79: 0 | W79: 0 | X79: 0 | Y79: 0 | Z79: 0 | AA79: 0 | AB79: 0 | AC79: 0 | AD79: 0 | AE79: 0 | AF79: 0 | AG79: 0 | AH79: 0 | AI79: 0 | AJ79: 0 | AK79: 0 | AL79: 0 | AM79: 0 | AN79: 0 | AO79: 0 | AP79: 0 | AQ79: 0 | AR79: 0 | AS79: 0 | AT79: 0 | AU79: 0 | AV79: 0 | AW79: NA | AY79: NA | AZ79: NA | BA79: 3 | BB79: 00169BBT | BE79: NA | BG79: NA | BH79: NA | BI79: NA | BJ79: NA | BK79: NA | BL79: NA | BO79: =IF(F79="","",_xlfn.CONCAT(I79&N79,IF(L79>M79,_xlfn.TEXTJOIN(,TRUE,O79:AV79),_xlfn.TEXTJOIN(,TRUE,AF79:AV79,O79:AE79)))) -> E141686000,72000000000000000000000000000000000 | BP79: =_xlfn.CONCAT(B79,N79,IF(L79>M79,_xlfn.TEXTJOIN(,TRUE,O79:AV79),_xlfn.TEXTJOIN(,TRUE,AF79:AV79,O79:AE79))) -> GMW171360,72000000000000000000000000000000000 | BQ79: =_xlfn.XLOOKUP(BO79,[1]Planilha1!$BU:$BU,[1]Planilha1!$BU:$BU,"",0,1)
A80: GEM | B80: GMW17136 | D80: =IF(_xlfn.XLOOKUP(C80,'Tabela de Familias'!A:A,'Tabela de Familias'!B:B)="","") | F80: SP746 | G80: =IF(F80="","",C80&"-"&F80) -> -SP746 | K80: E14168800 | L80: {=SUMPRODUCT(O80:AE80*$O$2:$AE$2)} -> 0.7 | M80: {=SUMPRODUCT(AF80:AV80*$AF$2:$AV$2)} -> 0.7 | N80: =L80+M80 -> 1.4 | O80: 2 | P80: 0 | Q80: 0 | R80: 0 | S80: 0 | T80: 0 | U80: 0 | V80: 0 | W80: 0 | X80: 0 | Y80: 0 | Z80: 0 | AA80: 0 | AB80: 0 | AC80: 0 | AD80: 0 | AE80: 0 | AF80: 2 | AG80: 0 | AH80: 0 | AI80: 0 | AJ80: 0 | AK80: 0 | AL80: 0 | AM80: 0 | AN80: 0 | AO80: 0 | AP80: 0 | AQ80: 0 | AR80: 0 | AS80: 0 | AT80: 0 | AU80: 0 | AV80: 0 | AW80: NA | AY80: NA | AZ80: NA | BA80: 3 | BB80: 00170BBT | BE80: NA | BG80: NA | BH80: NA | BI80: NA | BJ80: NA | BK80: NA | BL80: NA | BO80: =IF(F80="","",_xlfn.CONCAT(K80&N80,IF(L80>M80,_xlfn.TEXTJOIN(,TRUE,O80:AV80),_xlfn.TEXTJOIN(,TRUE,AF80:AV80,O80:AE80)))) -> E141688001,42000000000000000020000000000000000 | BP80: =_xlfn.CONCAT(B80,N80,IF(L80>M80,_xlfn.TEXTJOIN(,TRUE,O80:AV80),_xlfn.TEXTJOIN(,TRUE,AF80:AV80,O80:AE80))) -> GMW171361,42000000000000000020000000000000000 | BQ80: =_xlfn.XLOOKUP(BO80,[1]Planilha1!$BU:$BU,[1]Planilha1!$BU:$BU,"",0,1)
A81: GEM | B81: GMW17136 | D81: =IF(_xlfn.XLOOKUP(C81,'Tabela de Familias'!A:A,'Tabela de Familias'!B:B)="","") | F81: SP9 | G81: =IF(F81="","",C81&"-"&F81) -> -SP9 | K81: E14168800 | L81: {=SUMPRODUCT(O81:AE81*$O$2:$AE$2)} -> 1.4 | M81: {=SUMPRODUCT(AF81:AV81*$AF$2:$AV$2)} -> 0.35 | N81: =L81+M81 -> 1.75 | O81: 4 | P81: 0 | Q81: 0 | R81: 0 | S81: 0 | T81: 0 | U81: 0 | V81: 0 | W81: 0 | X81: 0 | Y81: 0 | Z81: 0 | AA81: 0 | AB81: 0 | AC81: 0 | AD81: 0 | AE81: 0 | AF81: 1 | AG81: 0 | AH81: 0 | AI81: 0 | AJ81: 0 | AK81: 0 | AL81: 0 | AM81: 0 | AN81: 0 | AO81: 0 | AP81: 0 | AQ81: 0 | AR81: 0 | AS81: 0 | AT81: 0 | AU81: 0 | AV81: 0 | AW81: NA | AY81: NA | AZ81: NA | BA81: 3 | BB81: 00171BBT | BE81: NA | BG81: NA | BH81: NA | BI81: NA | BJ81: NA | BK81: NA | BL81: NA | BO81: =IF(F81="","",_xlfn.CONCAT(K81&N81,IF(L81>M81,_xlfn.TEXTJOIN(,TRUE,O81:AV81),_xlfn.TEXTJOIN(,TRUE,AF81:AV81,O81:AE81)))) -> E141688001,754000000000000000010000000000000000 | BP81: =_xlfn.CONCAT(B81,N81,IF(L81>M81,_xlfn.TEXTJOIN(,TRUE,O81:AV81),_xlfn.TEXTJOIN(,TRUE,AF81:AV81,O81:AE81))) -> GMW171361,754000000000000000010000000000000000 | BQ81: =_xlfn.XLOOKUP(BO81,[1]Planilha1!$BU:$BU,[1]Planilha1!$BU:$BU,"",0,1)
A82: GEM | B82: GMW17136 | D82: =IF(_xlfn.XLOOKUP(C82,'Tabela de Familias'!A:A,'Tabela de Familias'!B:B)="","") | F82: SP9.00 | G82: =IF(F82="","",C82&"-"&F82) -> -SP9.00 | K82: E14168800 | L82: {=SUMPRODUCT(O82:AE82*$O$2:$AE$2)} -> 1.05 | M82: {=SUMPRODUCT(AF82:AV82*$AF$2:$AV$2)} -> 0.35 | N82: =L82+M82 -> 1.4 | O82: 3 | P82: 0 | Q82: 0 | R82: 0 | S82: 0 | T82: 0 | U82: 0 | V82: 0 | W82: 0 | X82: 0 | Y82: 0 | Z82: 0 | AA82: 0 | AB82: 0 | AC82: 0 | AD82: 0 | AE82: 0 | AF82: 1 | AG82: 0 | AH82: 0 | AI82: 0 | AJ82: 0 | AK82: 0 | AL82: 0 | AM82: 0 | AN82: 0 | AO82: 0 | AP82: 0 | AQ82: 0 | AR82: 0 | AS82: 0 | AT82: 0 | AU82: 0 | AV82: 0 | AW82: NA | AY82: NA | AZ82: NA | BA82: 3 | BB82: 00172BBT | BE82: NA | BG82: NA | BH82: NA | BI82: NA | BJ82: NA | BK82: NA | BL82: NA | BO82: =IF(F82="","",_xlfn.CONCAT(K82&N82,IF(L82>M82,_xlfn.TEXTJOIN(,TRUE,O82:AV82),_xlfn.TEXTJOIN(,TRUE,AF82:AV82,O82:AE82)))) -> E141688001,43000000000000000010000000000000000 | BP82: =_xlfn.CONCAT(B82,N82,IF(L82>M82,_xlfn.TEXTJOIN(,TRUE,O82:AV82),_xlfn.TEXTJOIN(,TRUE,AF82:AV82,O82:AE82))) -> GMW171361,43000000000000000010000000000000000 | BQ82: =_xlfn.XLOOKUP(BO82,[1]Planilha1!$BU:$BU,[1]Planilha1!$BU:$BU,"",0,1)
A83: GEM | B83: GMW17136 | D83: =IF(_xlfn.XLOOKUP(C83,'Tabela de Familias'!A:A,'Tabela de Familias'!B:B)="","") | F83: SP6281.00 | G83: =IF(F83="","",C83&"-"&F83) -> -SP6281.00 | K83: E02000700 | L83: {=SUMPRODUCT(O83:AE83*$O$2:$AE$2)} -> 0.85 | M83: {=SUMPRODUCT(AF83:AV83*$AF$2:$AV$2)} -> 0.85 | N83: =L83+M83 -> 1.7 | O83: 1 | P83: 1 | Q83: 0 | R83: 0 | S83: 0 | T83: 0 | U83: 0 | V83: 0 | W83: 0 | X83: 0 | Y83: 0 | Z83: 0 | AA83: 0 | AB83: 0 | AC83: 0 | AD83: 0 | AE83: 0 | AF83: 1 | AG83: 1 | AH83: 0 | AI83: 0 | AJ83: 0 | AK83: 0 | AL83: 0 | AM83: 0 | AN83: 0 | AO83: 0 | AP83: 0 | AQ83: 0 | AR83: 0 | AS83: 0 | AT83: 0 | AU83: 0 | AV83: 0 | AW83: NA | AY83: NA | AZ83: NA | BA83: 3 | BB83: 00173BBT | BE83: NA | BG83: NA | BH83: NA | BI83: NA | BJ83: NA | BK83: NA | BL83: NA | BO83: =IF(F83="","",_xlfn.CONCAT(K83&N83,IF(L83>M83,_xlfn.TEXTJOIN(,TRUE,O83:AV83),_xlfn.TEXTJOIN(,TRUE,AF83:AV83,O83:AE83)))) -> E020007001,71100000000000000011000000000000000 | BP83: =_xlfn.CONCAT(B83,N83,IF(L83>M83,_xlfn.TEXTJOIN(,TRUE,O83:AV83),_xlfn.TEXTJOIN(,TRUE,AF83:AV83,O83:AE83))) -> GMW171361,71100000000000000011000000000000000 | BQ83: =_xlfn.XLOOKUP(BO83,[1]Planilha1!$BU:$BU,[1]Planilha1!$BU:$BU,"",0,1)
A84: GEM | B84: GMW17136 | D84: =IF(_xlfn.XLOOKUP(C84,'Tabela de Familias'!A:A,'Tabela de Familias'!B:B)="","") | F84: SP1950 | G84: =IF(F84="","",C84&"-"&F84) -> -SP1950 | K84: E02000700 | L84: {=SUMPRODUCT(O84:AE84*$O$2:$AE$2)} -> 2 | M84: {=SUMPRODUCT(AF84:AV84*$AF$2:$AV$2)} -> 2 | N84: =L84+M84 -> 4 | O84: 0 | P84: 0 | Q84: 0 | R84: 2 | S84: 0 | T84: 0 | U84: 0 | V84: 0 | W84: 0 | X84: 0 | Y84: 0 | Z84: 0 | AA84: 0 | AB84: 0 | AC84: 0 | AD84: 0 | AE84: 0 | AF84: 0 | AG84: 0 | AH84: 0 | AI84: 2 | AJ84: 0 | AK84: 0 | AL84: 0 | AM84: 0 | AN84: 0 | AO84: 0 | AP84: 0 | AQ84: 0 | AR84: 0 | AS84: 0 | AT84: 0 | AU84: 0 | AV84: 0 | AW84: NA | AY84: NA | AZ84: NA | BA84: 3 | BB84: 00174BBT | BE84: NA | BG84: NA | BH84: NA | BI84: NA | BJ84: NA | BK84: NA | BL84: NA | BO84: =IF(F84="","",_xlfn.CONCAT(K84&N84,IF(L84>M84,_xlfn.TEXTJOIN(,TRUE,O84:AV84),_xlfn.TEXTJOIN(,TRUE,AF84:AV84,O84:AE84)))) -> E0200070040002000000000000000020000000000000 | BP84: =_xlfn.CONCAT(B84,N84,IF(L84>M84,_xlfn.TEXTJOIN(,TRUE,O84:AV84),_xlfn.TEXTJOIN(,TRUE,AF84:AV84,O84:AE84))) -> GMW1713640002000000000000000020000000000000 | BQ84: =_xlfn.XLOOKUP(BO84,[1]Planilha1!$BU:$BU,[1]Planilha1!$BU:$BU,"",0,1)
A85: GEM | B85: GMW17136 | D85: =IF(_xlfn.XLOOKUP(C85,'Tabela de Familias'!A:A,'Tabela de Familias'!B:B)="","") | F85: SP2129 | G85: =IF(F85="","",C85&"-"&F85) -> -SP2129 | K85: E02000700 | L85: {=SUMPRODUCT(O85:AE85*$O$2:$AE$2)} -> 1 | M85: {=SUMPRODUCT(AF85:AV85*$AF$2:$AV$2)} -> 1 | N85: =L85+M85 -> 2 | O85: 0 | P85: 2 | Q85: 0 | R85: 0 | S85: 0 | T85: 0 | U85: 0 | V85: 0 | W85: 0 | X85: 0 | Y85: 0 | Z85: 0 | AA85: 0 | AB85: 0 | AC85: 0 | AD85: 0 | AE85: 0 | AF85: 0 | AG85: 2 | AH85: 0 | AI85: 0 | AJ85: 0 | AK85: 0 | AL85: 0 | AM85: 0 | AN85: 0 | AO85: 0 | AP85: 0 | AQ85: 0 | AR85: 0 | AS85: 0 | AT85: 0 | AU85: 0 | AV85: 0 | AW85: NA | AY85: NA | AZ85: NA | BA85: 3 | BB85: 00175BBT | BE85: NA | BG85: NA | BH85: NA | BI85: NA | BJ85: NA | BK85: NA | BL85: NA | BO85: =IF(F85="","",_xlfn.CONCAT(K85&N85,IF(L85>M85,_xlfn.TEXTJOIN(,TRUE,O85:AV85),_xlfn.TEXTJOIN(,TRUE,AF85:AV85,O85:AE85)))) -> E0200070020200000000000000002000000000000000 | BP85: =_xlfn.CONCAT(B85,N85,IF(L85>M85,_xlfn.TEXTJOIN(,TRUE,O85:AV85),_xlfn.TEXTJOIN(,TRUE,AF85:AV85,O85:AE85))) -> GMW1713620200000000000000002000000000000000 | BQ85: =_xlfn.XLOOKUP(BO85,[1]Planilha1!$BU:$BU,[1]Planilha1!$BU:$BU,"",0,1)
A86: GEM | B86: GMW17136 | D86: =IF(_xlfn.XLOOKUP(C86,'Tabela de Familias'!A:A,'Tabela de Familias'!B:B)="","") | F86: SP5291 | G86: =IF(F86="","",C86&"-"&F86) -> -SP5291 | K86: E02000700 | L86: {=SUMPRODUCT(O86:AE86*$O$2:$AE$2)} -> 3.25 | M86: {=SUMPRODUCT(AF86:AV86*$AF$2:$AV$2)} -> 3 | N86: =L86+M86 -> 6.25 | O86: 0 | P86: 0 | Q86: 3 | R86: 1 | S86: 0 | T86: 0 | U86: 0 | V86: 0 | W86: 0 | X86: 0 | Y86: 0 | Z86: 0 | AA86: 0 | AB86: 0 | AC86: 0 | AD86: 0 | AE86: 0 | AF86: 0 | AG86: 0 | AH86: 0 | AI86: 3 | AJ86: 0 | AK86: 0 | AL86: 0 | AM86: 0 | AN86: 0 | AO86: 0 | AP86: 0 | AQ86: 0 | AR86: 0 | AS86: 0 | AT86: 0 | AU86: 0 | AV86: 0 | AW86: NA | AY86: NA | AZ86: NA | BA86: 3 | BB86: 00176BBT | BE86: NA | BG86: NA | BH86: NA | BI86: NA | BJ86: NA | BK86: NA | BL86: NA | BO86: =IF(F86="","",_xlfn.CONCAT(K86&N86,IF(L86>M86,_xlfn.TEXTJOIN(,TRUE,O86:AV86),_xlfn.TEXTJOIN(,TRUE,AF86:AV86,O86:AE86)))) -> E020007006,250031000000000000000030000000000000 | BP86: =_xlfn.CONCAT(B86,N86,IF(L86>M86,_xlfn.TEXTJOIN(,TRUE,O86:AV86),_xlfn.TEXTJOIN(,TRUE,AF86:AV86,O86:AE86))) -> GMW171366,250031000000000000000030000000000000 | BQ86: =_xlfn.XLOOKUP(BO86,[1]Planilha1!$BU:$BU,[1]Planilha1!$BU:$BU,"",0,1)
A87: GEM | B87: GMW17136 | D87: =IF(_xlfn.XLOOKUP(C87,'Tabela de Familias'!A:A,'Tabela de Familias'!B:B)="","") | F87: SP5291.00 | G87: =IF(F87="","",C87&"-"&F87) -> -SP5291.00 | K87: E02000700 | L87: {=SUMPRODUCT(O87:AE87*$O$2:$AE$2)} -> 3 | M87: {=SUMPRODUCT(AF87:AV87*$AF$2:$AV$2)} -> 2.5 | N87: =L87+M87 -> 5.5 | O87: 0 | P87: 0 | Q87: 0 | R87: 3 | S87: 0 | T87: 0 | U87: 0 | V87: 0 | W87: 0 | X87: 0 | Y87: 0 | Z87: 0 | AA87: 0 | AB87: 0 | AC87: 0 | AD87: 0 | AE87: 0 | AF87: 0 | AG87: 3 | AH87: 0 | AI87: 1 | AJ87: 0 | AK87: 0 | AL87: 0 | AM87: 0 | AN87: 0 | AO87: 0 | AP87: 0 | AQ87: 0 | AR87: 0 | AS87: 0 | AT87: 0 | AU87: 0 | AV87: 0 | AW87: NA | AY87: NA | AZ87: NA | BA87: 3 | BB87: 00177BBT | BE87: NA | BG87: NA | BH87: NA | BI87: NA | BJ87: NA | BK87: NA | BL87: NA | BO87: =IF(F87="","",_xlfn.CONCAT(K87&N87,IF(L87>M87,_xlfn.TEXTJOIN(,TRUE,O87:AV87),_xlfn.TEXTJOIN(,TRUE,AF87:AV87,O87:AE87)))) -> E020007005,50003000000000000003010000000000000 | BP87: =_xlfn.CONCAT(B87,N87,IF(L87>M87,_xlfn.TEXTJOIN(,TRUE,O87:AV87),_xlfn.TEXTJOIN(,TRUE,AF87:AV87,O87:AE87))) -> GMW171365,50003000000000000003010000000000000 | BQ87: =_xlfn.XLOOKUP(BO87,[1]Planilha1!$BU:$BU,[1]Planilha1!$BU:$BU,"",0,1)
A88: GEM | B88: GMW17136 | D88: =IF(_xlfn.XLOOKUP(C88,'Tabela de Familias'!A:A,'Tabela de Familias'!B:B)="","") | F88: SP5292 | G88: =IF(F88="","",C88&"-"&F88) -> -SP5292 | K88: E14168600 | L88: {=SUMPRODUCT(O88:AE88*$O$2:$AE$2)} -> 3 | M88: {=SUMPRODUCT(AF88:AV88*$AF$2:$AV$2)} -> 1 | N88: =L88+M88 -> 4 | O88: 0 | P88: 6 | Q88: 0 | R88: 0 | S88: 0 | T88: 0 | U88: 0 | V88: 0 | W88: 0 | X88: 0 | Y88: 0 | Z88: 0 | AA88: 0 | AB88: 0 | AC88: 0 | AD88: 0 | AE88: 0 | AF88: 0 | AG88: 2 | AH88: 0 | AI88: 0 | AJ88: 0 | AK88: 0 | AL88: 0 | AM88: 0 | AN88: 0 | AO88: 0 | AP88: 0 | AQ88: 0 | AR88: 0 | AS88: 0 | AT88: 0 | AU88: 0 | AV88: 0 | AW88: NA | AY88: NA | AZ88: NA | BA88: 3 | BB88: 00178BBT | BE88: NA | BG88: NA | BH88: NA | BI88: NA | BJ88: NA | BK88: NA | BL88: NA | BO88: =IF(F88="","",_xlfn.CONCAT(K88&N88,IF(L88>M88,_xlfn.TEXTJOIN(,TRUE,O88:AV88),_xlfn.TEXTJOIN(,TRUE,AF88:AV88,O88:AE88)))) -> E1416860040600000000000000002000000000000000 | BP88: =_xlfn.CONCAT(B88,N88,IF(L88>M88,_xlfn.TEXTJOIN(,TRUE,O88:AV88),_xlfn.TEXTJOIN(,TRUE,AF88:AV88,O88:AE88))) -> GMW1713640600000000000000002000000000000000 | BQ88: =_xlfn.XLOOKUP(BO88,[1]Planilha1!$BU:$BU,[1]Planilha1!$BU:$BU,"",0,1)
A89: GEM | B89: GMW17136 | D89: =IF(_xlfn.XLOOKUP(C89,'Tabela de Familias'!A:A,'Tabela de Familias'!B:B)="","") | F89: X11SP6281.00 | G89: =IF(F89="","",C89&"-"&F89) -> -X11SP6281.00 | K89: E02000700 | L89: {=SUMPRODUCT(O89:AE89*$O$2:$AE$2)} -> 1 | M89: {=SUMPRODUCT(AF89:AV89*$AF$2:$AV$2)} -> 0.85 | N89: =L89+M89 -> 1.85 | O89: 0 | P89: 2 | Q89: 0 | R89: 0 | S89: 0 | T89: 0 | U89: 0 | V89: 0 | W89: 0 | X89: 0 | Y89: 0 | Z89: 0 | AA89: 0 | AB89: 0 | AC89: 0 | AD89: 0 | AE89: 0 | AF89: 1 | AG89: 1 | AH89: 0 | AI89: 0 | AJ89: 0 | AK89: 0 | AL89: 0 | AM89: 0 | AN89: 0 | AO89: 0 | AP89: 0 | AQ89: 0 | AR89: 0 | AS89: 0 | AT89: 0 | AU89: 0 | AV89: 0 | AW89: NA | AY89: NA | AZ89: NA | BA89: 3 | BB89: 00179BBT | BE89: NA | BG89: NA | BH89: NA | BI89: NA | BJ89: NA | BK89: NA | BL89: NA | BO89: =IF(F89="","",_xlfn.CONCAT(K89&N89,IF(L89>M89,_xlfn.TEXTJOIN(,TRUE,O89:AV89),_xlfn.TEXTJOIN(,TRUE,AF89:AV89,O89:AE89)))) -> E020007001,850200000000000000011000000000000000 | BP89: =_xlfn.CONCAT(B89,N89,IF(L89>M89,_xlfn.TEXTJOIN(,TRUE,O89:AV89),_xlfn.TEXTJOIN(,TRUE,AF89:AV89,O89:AE89))) -> GMW171361,850200000000000000011000000000000000 | BQ89: =_xlfn.XLOOKUP(BO89,[1]Planilha1!$BU:$BU,[1]Planilha1!$BU:$BU,"",0,1)
A90: GEM | B90: GMW17136 | D90: =IF(_xlfn.XLOOKUP(C90,'Tabela de Familias'!A:A,'Tabela de Familias'!B:B)="","") | F90: SP1950 | G90: =IF(F90="","",C90&"-"&F90) -> -SP1950 | K90: E02000700 | L90: {=SUMPRODUCT(O90:AE90*$O$2:$AE$2)} -> 3 | M90: {=SUMPRODUCT(AF90:AV90*$AF$2:$AV$2)} -> 1 | N90: =L90+M90 -> 4 | O90: 0 | P90: 0 | Q90: 0 | R90: 3 | S90: 0 | T90: 0 | U90: 0 | V90: 0 | W90: 0 | X90: 0 | Y90: 0 | Z90: 0 | AA90: 0 | AB90: 0 | AC90: 0 | AD90: 0 | AE90: 0 | AF90: 0 | AG90: 0 | AH90: 0 | AI90: 1 | AJ90: 0 | AK90: 0 | AL90: 0 | AM90: 0 | AN90: 0 | AO90: 0 | AP90: 0 | AQ90: 0 | AR90: 0 | AS90: 0 | AT90: 0 | AU90: 0 | AV90: 0 | AW90: NA | AY90: NA | AZ90: NA | BA90: 3 | BB90: 00180BBT | BE90: NA | BG90: NA | BH90: NA | BI90: NA | BJ90: NA | BK90: NA | BL90: NA | BO90: =IF(F90="","",_xlfn.CONCAT(K90&N90,IF(L90>M90,_xlfn.TEXTJOIN(,TRUE,O90:AV90),_xlfn.TEXTJOIN(,TRUE,AF90:AV90,O90:AE90)))) -> E0200070040003000000000000000010000000000000 | BP90: =_xlfn.CONCAT(B90,N90,IF(L90>M90,_xlfn.TEXTJOIN(,TRUE,O90:AV90),_xlfn.TEXTJOIN(,TRUE,AF90:AV90,O90:AE90))) -> GMW1713640003000000000000000010000000000000 | BQ90: =_xlfn.XLOOKUP(BO90,[1]Planilha1!$BU:$BU,[1]Planilha1!$BU:$BU,"",0,1)
A91: GEM | B91: GMW17136 | D91: =IF(_xlfn.XLOOKUP(C91,'Tabela de Familias'!A:A,'Tabela de Familias'!B:B)="","") | F91: SP2129 | G91: =IF(F91="","",C91&"-"&F91) -> -SP2129 | K91: E02000700 | L91: {=SUMPRODUCT(O91:AE91*$O$2:$AE$2)} -> 1.5 | M91: {=SUMPRODUCT(AF91:AV91*$AF$2:$AV$2)} -> 0.5 | N91: =L91+M91 -> 2 | O91: 0 | P91: 3 | Q91: 0 | R91: 0 | S91: 0 | T91: 0 | U91: 0 | V91: 0 | W91: 0 | X91: 0 | Y91: 0 | Z91: 0 | AA91: 0 | AB91: 0 | AC91: 0 | AD91: 0 | AE91: 0 | AF91: 0 | AG91: 1 | AH91: 0 | AI91: 0 | AJ91: 0 | AK91: 0 | AL91: 0 | AM91: 0 | AN91: 0 | AO91: 0 | AP91: 0 | AQ91: 0 | AR91: 0 | AS91: 0 | AT91: 0 | AU91: 0 | AV91: 0 | AW91: NA | AY91: NA | AZ91: NA | BA91: 3 | BB91: 00181BBT | BE91: NA | BG91: NA | BH91: NA | BI91: NA | BJ91: NA | BK91: NA | BL91: NA | BO91: =IF(F91="","",_xlfn.CONCAT(K91&N91,IF(L91>M91,_xlfn.TEXTJOIN(,TRUE,O91:AV91),_xlfn.TEXTJOIN(,TRUE,AF91:AV91,O91:AE91)))) -> E0200070020300000000000000001000000000000000 | BP91: =_xlfn.CONCAT(B91,N91,IF(L91>M91,_xlfn.TEXTJOIN(,TRUE,O91:AV91),_xlfn.TEXTJOIN(,TRUE,AF91:AV91,O91:AE91))) -> GMW1713620300000000000000001000000000000000 | BQ91: =_xlfn.XLOOKUP(BO91,[1]Planilha1!$BU:$BU,[1]Planilha1!$BU:$BU,"",0,1)
... A127: GEM | B127: GMW17136 | D127: =IF(_xlfn.XLOOKUP(C127,'Tabela de Familias'!A:A,'Tabela de Familias'!B:B)="","") | F127: SP1361 | G127: =IF(F127="","",C127&"-"&F127) -> -SP1361 | K127: E14168800 | L127: {=SUMPRODUCT(O127:AE127*$O$2:$AE$2)} -> 1.7 | M127: {=SUMPRODUCT(AF127:AV127*$AF$2:$AV$2)} -> 1.35 | N127: =L127+M127 -> 3.05 | O127: 2 | P127: 2 | Q127: 0 | R127: 0 | S127: 0 | T127: 0 | U127: 0 | V127: 0 | W127: 0 | X127: 0 | Y127: 0 | Z127: 0 | AA127: 0 | AB127: 0 | AC127: 0 | AD127: 0 | AE127: 0 | AF127: 1 | AG127: 2 | AH127: 0 | AI127: 0 | AJ127: 0 | AK127: 0 | AL127: 0 | AM127: 0 | AN127: 0 | AO127: 0 | AP127: 0 | AQ127: 0 | AR127: 0 | AS127: 0 | AT127: 0 | AU127: 0 | AV127: 0 | AW127: NA | AY127: NA | AZ127: NA | BA127: 3 | BB127: 0048BBT | BE127: NA | BG127: NA | BH127: NA | BI127: NA | BJ127: NA | BK127: NA | BL127: NA | BO127: =IF(F127="","",_xlfn.CONCAT(K127&N127,IF(L127>M127,_xlfn.TEXTJOIN(,TRUE,O127:AV127),_xlfn.TEXTJOIN(,TRUE,AF127:AV127,O127:AE127)))) -> E141688003,052200000000000000012000000000000000 | BP127: =_xlfn.CONCAT(B127,N127,IF(L127>M127,_xlfn.TEXTJOIN(,TRUE,O127:AV127),_xlfn.TEXTJOIN(,TRUE,AF127:AV127,O127:AE127))) -> GMW171363,052200000000000000012000000000000000 | BQ127: =_xlfn.XLOOKUP(BO127,[1]Planilha1!$BU:$BU,[1]Planilha1!$BU:$BU,"",0,1)
A128: SPIN | B128: GMW17136 | D128: =IF(_xlfn.XLOOKUP(C128,'Tabela de Familias'!A:A,'Tabela de Familias'!B:B)="","") | E128: SOLDA LINEAR | F128: SP2374_X1 | G128: =IF(F128="","",C128&"-"&F128) -> -SP2374_X1 | K128: E16718500 | L128: {=SUMPRODUCT(O128:AE128*$O$2:$AE$2)} -> 1 | M128: {=SUMPRODUCT(AF128:AV128*$AF$2:$AV$2)} -> 1 | N128: =L128+M128 -> 2 | O128: 0 | P128: 2 | Q128: 0 | R128: 0 | S128: 0 | T128: 0 | U128: 0 | V128: 0 | W128: 0 | X128: 0 | Y128: 0 | Z128: 0 | AA128: 0 | AB128: 0 | AC128: 0 | AD128: 0 | AE128: 0 | AF128: 0 | AG128: 2 | AH128: 0 | AI128: 0 | AJ128: 0 | AK128: 0 | AL128: 0 | AM128: 0 | AN128: 0 | AO128: 0 | AP128: 0 | AQ128: 0 | AR128: 0 | AS128: 0 | AT128: 0 | AU128: 0 | AV128: 0 | AW128: NA | AY128: NA | AZ128: NA | BA128: 125 | BB128: 015BTSPIN | BC128: 45027 | BE128: NA | BG128: NA | BH128: NA | BI128: NA | BJ128: NA | BK128: NA | BL128: NA | BO128: =IF(F128="","",_xlfn.CONCAT(K128&N128,IF(L128>M128,_xlfn.TEXTJOIN(,TRUE,O128:AV128),_xlfn.TEXTJOIN(,TRUE,AF128:AV128,O128:AE128)))) -> E1671850020200000000000000002000000000000000 | BP128: =_xlfn.CONCAT(B128,N128,IF(L128>M128,_xlfn.TEXTJOIN(,TRUE,O128:AV128),_xlfn.TEXTJOIN(,TRUE,AF128:AV128,O128:AE128))) -> GMW1713620200000000000000002000000000000000 | BQ128: =_xlfn.XLOOKUP(BO128,[1]Planilha1!$BU:$BU,[1]Planilha1!$BU:$BU,"",0,1) -> E1671850020200000000000000002000000000000000
A129: SPIN | B129: GMW17136 | D129: =IF(_xlfn.XLOOKUP(C129,'Tabela de Familias'!A:A,'Tabela de Familias'!B:B)="","") | E129: SOLDA LINEAR | F129: SP2374_X1.00 | G129: =IF(F129="","",C129&"-"&F129) -> -SP2374_X1.00 | K129: E16718500 | L129: {=SUMPRODUCT(O129:AE129*$O$2:$AE$2)} -> 1.5 | M129: {=SUMPRODUCT(AF129:AV129*$AF$2:$AV$2)} -> 1.5 | N129: =L129+M129 -> 3 | O129: 0 | P129: 3 | Q129: 0 | R129: 0 | S129: 0 | T129: 0 | U129: 0 | V129: 0 | W129: 0 | X129: 0 | Y129: 0 | Z129: 0 | AA129: 0 | AB129: 0 | AC129: 0 | AD129: 0 | AE129: 0 | AF129: 0 | AG129: 3 | AH129: 0 | AI129: 0 | AJ129: 0 | AK129: 0 | AL129: 0 | AM129: 0 | AN129: 0 | AO129: 0 | AP129: 0 | AQ129: 0 | AR129: 0 | AS129: 0 | AT129: 0 | AU129: 0 | AV129: 0 | AW129: NA | AY129: NA | AZ129: NA | BA129: 125 | BB129: 018BTSPIN | BC129: 45034 | BE129: NA | BG129: NA | BH129: NA | BI129: NA | BJ129: NA | BK129: NA | BL129: NA | BO129: =IF(F129="","",_xlfn.CONCAT(K129&N129,IF(L129>M129,_xlfn.TEXTJOIN(,TRUE,O129:AV129),_xlfn.TEXTJOIN(,TRUE,AF129:AV129,O129:AE129)))) -> E1671850030300000000000000003000000000000000 | BP129: =_xlfn.CONCAT(B129,N129,IF(L129>M129,_xlfn.TEXTJOIN(,TRUE,O129:AV129),_xlfn.TEXTJOIN(,TRUE,AF129:AV129,O129:AE129))) -> GMW1713630300000000000000003000000000000000 | BQ129: =_xlfn.XLOOKUP(BO129,[1]Planilha1!$BU:$BU,[1]Planilha1!$BU:$BU,"",0,1) -> E1671850030300000000000000003000000000000000
